[2024-08-28 00:14:48,013][root.tracker][INFO] - Loading weights from deep_sort_pytorch/deep_sort/deep/checkpoint/ckpt.t7... Done!
[2024-08-28 00:18:03,231][root.tracker][INFO] - Loading weights from deep_sort_pytorch/deep_sort/deep/checkpoint/ckpt.t7... Done!
[2024-08-28 00:22:19,266][root.tracker][INFO] - Loading weights from deep_sort_pytorch/deep_sort/deep/checkpoint/ckpt.t7... Done!
[2024-08-28 08:41:26,275][root.tracker][INFO] - Loading weights from deep_sort_pytorch/deep_sort/deep/checkpoint/ckpt.t7... Done!
[2024-08-28 11:26:58,923][root.tracker][INFO] - Loading weights from deep_sort_pytorch/deep_sort/deep/checkpoint/ckpt.t7... Done!
[2024-09-03 19:27:32,443][root.tracker][INFO] - Loading weights from deep_sort_pytorch/deep_sort/deep/checkpoint/ckpt.t7... Done!
[2024-09-03 20:52:32,950][root.tracker][INFO] - Loading weights from deep_sort_pytorch/deep_sort/deep/checkpoint/ckpt.t7... Done!
[2024-09-03 20:58:21,931][root.tracker][INFO] - Loading weights from deep_sort_pytorch/deep_sort/deep/checkpoint/ckpt.t7... Done!
[2024-09-03 21:09:14,332][root.tracker][INFO] - Loading weights from deep_sort_pytorch/deep_sort/deep/checkpoint/ckpt.t7... Done!
[2024-09-03 21:16:11,759][root.tracker][INFO] - Loading weights from deep_sort_pytorch/deep_sort/deep/checkpoint/ckpt.t7... Done!
[2024-09-04 09:42:41,718][root.tracker][INFO] - Loading weights from deep_sort_pytorch/deep_sort/deep/checkpoint/ckpt.t7... Done!
[2024-09-04 12:07:23,238][root.tracker][INFO] - Loading weights from deep_sort_pytorch/deep_sort/deep/checkpoint/ckpt.t7... Done!
[2024-09-04 12:07:43,790][root.tracker][INFO] - Loading weights from deep_sort_pytorch/deep_sort/deep/checkpoint/ckpt.t7... Done!
[2024-09-04 15:58:31,008][root.tracker][INFO] - Loading weights from deep_sort_pytorch/deep_sort/deep/checkpoint/ckpt.t7... Done!
[2024-09-04 16:27:59,157][root.tracker][INFO] - Loading weights from deep_sort_pytorch/deep_sort/deep/checkpoint/ckpt.t7... Done!
[2024-09-04 16:29:10,166][root.tracker][INFO] - Loading weights from deep_sort_pytorch/deep_sort/deep/checkpoint/ckpt.t7... Done!
[2024-09-17 22:30:14,845][root.tracker][INFO] - Loading weights from deep_sort_pytorch/deep_sort/deep/checkpoint/ckpt.t7... Done!
[2024-09-17 23:30:46,759][root.tracker][INFO] - Loading weights from deep_sort_pytorch/deep_sort/deep/checkpoint/ckpt.t7... Done!
[2024-09-18 16:14:06,591][root.tracker][INFO] - Loading weights from deep_sort_pytorch/deep_sort/deep/checkpoint/ckpt.t7... Done!
[2024-09-18 16:15:43,824][root.tracker][INFO] - Loading weights from deep_sort_pytorch/deep_sort/deep/checkpoint/ckpt.t7... Done!
[2024-09-18 16:16:37,727][root.tracker][INFO] - Loading weights from deep_sort_pytorch/deep_sort/deep/checkpoint/ckpt.t7... Done!
[2024-09-18 16:22:05,868][root.tracker][INFO] - Loading weights from deep_sort_pytorch/deep_sort/deep/checkpoint/ckpt.t7... Done!
[2024-10-16 10:44:44,877][root.tracker][INFO] - Loading weights from deep_sort_pytorch/deep_sort/deep/checkpoint/ckpt.t7... Done!
[2024-10-18 11:00:10,202][root.tracker][INFO] - Loading weights from deep_sort_pytorch/deep_sort/deep/checkpoint/ckpt.t7... Done!
[2024-10-18 11:01:43,321][root.tracker][INFO] - Loading weights from deep_sort_pytorch/deep_sort/deep/checkpoint/ckpt.t7... Done!
[2024-10-18 11:04:44,575][root.tracker][INFO] - Loading weights from deep_sort_pytorch/deep_sort/deep/checkpoint/ckpt.t7... Done!
[2024-10-18 11:06:05,173][root.tracker][INFO] - Loading weights from deep_sort_pytorch/deep_sort/deep/checkpoint/ckpt.t7... Done!
[2024-10-18 11:07:22,571][root.tracker][INFO] - Loading weights from deep_sort_pytorch/deep_sort/deep/checkpoint/ckpt.t7... Done!
[2024-10-18 11:08:24,172][root.tracker][INFO] - Loading weights from deep_sort_pytorch/deep_sort/deep/checkpoint/ckpt.t7... Done!
[2024-10-22 15:34:43,412][root.tracker][INFO] - Loading weights from deep_sort_pytorch/deep_sort/deep/checkpoint/ckpt.t7... Done!
[2024-10-22 17:17:47,961][root.tracker][INFO] - Loading weights from deep_sort_pytorch/deep_sort/deep/checkpoint/ckpt.t7... Done!
[2024-10-22 17:23:40,497][root.tracker][INFO] - Loading weights from deep_sort_pytorch/deep_sort/deep/checkpoint/ckpt.t7... Done!
[2024-10-22 17:25:35,518][root.tracker][INFO] - Loading weights from deep_sort_pytorch/deep_sort/deep/checkpoint/ckpt.t7... Done!
[2024-10-22 17:25:55,834][root.tracker][INFO] - Loading weights from deep_sort_pytorch/deep_sort/deep/checkpoint/ckpt.t7... Done!
[2024-10-22 17:27:03,271][root.tracker][INFO] - Loading weights from deep_sort_pytorch/deep_sort/deep/checkpoint/ckpt.t7... Done!
[2024-10-22 17:31:40,972][root.tracker][INFO] - Loading weights from deep_sort_pytorch/deep_sort/deep/checkpoint/ckpt.t7... Done!
[2024-10-22 17:38:27,372][root.tracker][INFO] - Loading weights from deep_sort_pytorch/deep_sort/deep/checkpoint/ckpt.t7... Done!
[2024-10-22 18:27:55,400][root.tracker][INFO] - Loading weights from deep_sort_pytorch/deep_sort/deep/checkpoint/ckpt.t7... Done!
[2024-10-22 18:38:47,409][root.tracker][INFO] - Loading weights from deep_sort_pytorch/deep_sort/deep/checkpoint/ckpt.t7... Done!
[2024-10-22 18:39:45,318][root.tracker][INFO] - Loading weights from deep_sort_pytorch/deep_sort/deep/checkpoint/ckpt.t7... Done!
[2024-10-22 18:40:08,253][root.tracker][INFO] - Loading weights from deep_sort_pytorch/deep_sort/deep/checkpoint/ckpt.t7... Done!
[2024-10-22 18:40:29,660][root.tracker][INFO] - Loading weights from deep_sort_pytorch/deep_sort/deep/checkpoint/ckpt.t7... Done!
[2024-10-22 18:48:41,695][root.tracker][INFO] - Loading weights from deep_sort_pytorch/deep_sort/deep/checkpoint/ckpt.t7... Done!
[2024-10-22 19:12:16,657][root.tracker][INFO] - Loading weights from deep_sort_pytorch/deep_sort/deep/checkpoint/ckpt.t7... Done!
[2024-10-22 19:13:58,712][root.tracker][INFO] - Loading weights from deep_sort_pytorch/deep_sort/deep/checkpoint/ckpt.t7... Done!
[2024-10-22 19:15:52,075][root.tracker][INFO] - Loading weights from deep_sort_pytorch/deep_sort/deep/checkpoint/ckpt.t7... Done!
[2024-10-22 19:21:33,220][root.tracker][INFO] - Loading weights from deep_sort_pytorch/deep_sort/deep/checkpoint/ckpt.t7... Done!
[2024-10-22 19:22:31,393][root.tracker][INFO] - Loading weights from deep_sort_pytorch/deep_sort/deep/checkpoint/ckpt.t7... Done!
[2024-10-22 19:23:18,623][root.tracker][INFO] - Loading weights from deep_sort_pytorch/deep_sort/deep/checkpoint/ckpt.t7... Done!
[2024-10-22 19:24:20,972][root.tracker][INFO] - Loading weights from deep_sort_pytorch/deep_sort/deep/checkpoint/ckpt.t7... Done!
[2024-10-22 19:26:11,761][root.tracker][INFO] - Loading weights from deep_sort_pytorch/deep_sort/deep/checkpoint/ckpt.t7... Done!
[2024-10-22 19:27:30,179][root.tracker][INFO] - Loading weights from deep_sort_pytorch/deep_sort/deep/checkpoint/ckpt.t7... Done!
[2024-10-22 19:28:03,371][root.tracker][INFO] - Loading weights from deep_sort_pytorch/deep_sort/deep/checkpoint/ckpt.t7... Done!
[2024-10-22 19:29:54,567][root.tracker][INFO] - Loading weights from deep_sort_pytorch/deep_sort/deep/checkpoint/ckpt.t7... Done!
[2024-10-22 19:36:28,780][root.tracker][INFO] - Loading weights from deep_sort_pytorch/deep_sort/deep/checkpoint/ckpt.t7... Done!
[2024-10-22 19:37:38,020][root.tracker][INFO] - Loading weights from deep_sort_pytorch/deep_sort/deep/checkpoint/ckpt.t7... Done!
[2024-10-22 19:37:58,515][root.tracker][INFO] - Loading weights from deep_sort_pytorch/deep_sort/deep/checkpoint/ckpt.t7... Done!
[2024-10-22 19:38:36,548][root.tracker][INFO] - Loading weights from deep_sort_pytorch/deep_sort/deep/checkpoint/ckpt.t7... Done!
[2024-10-22 19:41:00,122][root.tracker][INFO] - Loading weights from deep_sort_pytorch/deep_sort/deep/checkpoint/ckpt.t7... Done!
[2024-10-22 19:41:14,218][root.tracker][INFO] - Loading weights from deep_sort_pytorch/deep_sort/deep/checkpoint/ckpt.t7... Done!
[2024-10-22 19:44:57,684][root.tracker][INFO] - Loading weights from deep_sort_pytorch/deep_sort/deep/checkpoint/ckpt.t7... Done!
[2024-10-22 19:50:47,132][root.tracker][INFO] - Loading weights from deep_sort_pytorch/deep_sort/deep/checkpoint/ckpt.t7... Done!
[2024-10-22 20:20:17,579][root.tracker][INFO] - Loading weights from deep_sort_pytorch/deep_sort/deep/checkpoint/ckpt.t7... Done!
[2024-10-22 20:24:12,973][root.tracker][INFO] - Loading weights from deep_sort_pytorch/deep_sort/deep/checkpoint/ckpt.t7... Done!
[2024-10-22 20:26:42,818][root.tracker][INFO] - Loading weights from deep_sort_pytorch/deep_sort/deep/checkpoint/ckpt.t7... Done!
[2024-10-22 20:29:27,662][root.tracker][INFO] - Loading weights from deep_sort_pytorch/deep_sort/deep/checkpoint/ckpt.t7... Done!
[2024-10-22 20:30:52,017][root.tracker][INFO] - Loading weights from deep_sort_pytorch/deep_sort/deep/checkpoint/ckpt.t7... Done!
[2024-10-22 20:36:37,741][root.tracker][INFO] - Loading weights from deep_sort_pytorch/deep_sort/deep/checkpoint/ckpt.t7... Done!
[2024-10-23 17:12:35,881][root.tracker][INFO] - Loading weights from deep_sort_pytorch/deep_sort/deep/checkpoint/ckpt.t7... Done!
[2024-10-24 20:51:47,549][root.tracker][INFO] - Loading weights from deep_sort_pytorch/deep_sort/deep/checkpoint/ckpt.t7... Done!
[2024-10-24 21:33:07,044][root.tracker][INFO] - Loading weights from deep_sort_pytorch/deep_sort/deep/checkpoint/ckpt.t7... Done!
[2024-10-24 22:14:14,320][root.tracker][INFO] - Loading weights from deep_sort_pytorch/deep_sort/deep/checkpoint/ckpt.t7... Done!
[2024-10-25 16:43:52,348][root.tracker][INFO] - Loading weights from deep_sort_pytorch/deep_sort/deep/checkpoint/ckpt.t7... Done!
[2024-10-25 18:43:16,570][root.tracker][INFO] - Loading weights from deep_sort_pytorch/deep_sort/deep/checkpoint/ckpt.t7... Done!
[2024-10-25 18:52:11,791][root.tracker][INFO] - Loading weights from deep_sort_pytorch/deep_sort/deep/checkpoint/ckpt.t7... Done!
[2024-10-25 18:55:17,300][root.tracker][INFO] - Loading weights from deep_sort_pytorch/deep_sort/deep/checkpoint/ckpt.t7... Done!
[2024-10-25 19:01:11,243][root.tracker][INFO] - Loading weights from deep_sort_pytorch/deep_sort/deep/checkpoint/ckpt.t7... Done!
[2024-10-30 12:26:11,152][root.tracker][INFO] - Loading weights from deep_sort_pytorch/deep_sort/deep/checkpoint/ckpt.t7... Done!
[2024-10-30 13:26:36,131][root.tracker][INFO] - Loading weights from deep_sort_pytorch/deep_sort/deep/checkpoint/ckpt.t7... Done!
[2024-10-30 13:27:20,274][root.tracker][INFO] - Loading weights from deep_sort_pytorch/deep_sort/deep/checkpoint/ckpt.t7... Done!
[2024-10-30 14:44:46,421][root.tracker][INFO] - Loading weights from deep_sort_pytorch/deep_sort/deep/checkpoint/ckpt.t7... Done!
[2024-11-01 22:26:04,499][root.tracker][INFO] - Loading weights from deep_sort_pytorch/deep_sort/deep/checkpoint/ckpt.t7... Done!
[2024-11-04 20:22:18,650][root.tracker][INFO] - Loading weights from deep_sort_pytorch/deep_sort/deep/checkpoint/ckpt.t7... Done!
[2024-11-04 20:26:14,585][root.tracker][INFO] - Loading weights from deep_sort_pytorch/deep_sort/deep/checkpoint/ckpt.t7... Done!
[2024-11-04 20:28:58,676][root.tracker][INFO] - Loading weights from deep_sort_pytorch/deep_sort/deep/checkpoint/ckpt.t7... Done!
[2024-11-04 20:30:36,552][root.tracker][INFO] - Loading weights from deep_sort_pytorch/deep_sort/deep/checkpoint/ckpt.t7... Done!
[2024-11-06 09:16:36,391][root.tracker][INFO] - Loading weights from deep_sort_pytorch/deep_sort/deep/checkpoint/ckpt.t7... Done!
[2024-11-06 09:17:15,897][root.tracker][INFO] - Loading weights from deep_sort_pytorch/deep_sort/deep/checkpoint/ckpt.t7... Done!
[2024-11-07 02:36:40,169][root.tracker][INFO] - Loading weights from deep_sort_pytorch/deep_sort/deep/checkpoint/ckpt.t7... Done!
[2024-11-07 13:11:02,604][root.tracker][INFO] - Loading weights from deep_sort_pytorch/deep_sort/deep/checkpoint/ckpt.t7... Done!
[2024-11-07 14:12:26,914][grpc._plugin_wrapping][ERROR] - AuthMetadataPluginCallback "<google.auth.transport.grpc.AuthMetadataPlugin object at 0x0000029BDCBA9A60>" raised exception!
Traceback (most recent call last):
  File "C:\Users\nifei\Downloads\DeepSort_Tutorial\.venv\Lib\site-packages\urllib3\connection.py", line 196, in _new_conn
    sock = connection.create_connection(
           ^^^^^^^^^^^^^^^^^^^^^^^^^^^^^
  File "C:\Users\nifei\Downloads\DeepSort_Tutorial\.venv\Lib\site-packages\urllib3\util\connection.py", line 60, in create_connection
    for res in socket.getaddrinfo(host, port, family, socket.SOCK_STREAM):
               ^^^^^^^^^^^^^^^^^^^^^^^^^^^^^^^^^^^^^^^^^^^^^^^^^^^^^^^^^^
  File "C:\Users\nifei\AppData\Local\Programs\Python\Python312\Lib\socket.py", line 963, in getaddrinfo
    for res in _socket.getaddrinfo(host, port, family, type, proto, flags):
               ^^^^^^^^^^^^^^^^^^^^^^^^^^^^^^^^^^^^^^^^^^^^^^^^^^^^^^^^^^^
socket.gaierror: [Errno 11001] getaddrinfo failed

The above exception was the direct cause of the following exception:

Traceback (most recent call last):
  File "C:\Users\nifei\Downloads\DeepSort_Tutorial\.venv\Lib\site-packages\urllib3\connectionpool.py", line 789, in urlopen
    response = self._make_request(
               ^^^^^^^^^^^^^^^^^^^
  File "C:\Users\nifei\Downloads\DeepSort_Tutorial\.venv\Lib\site-packages\urllib3\connectionpool.py", line 490, in _make_request
    raise new_e
  File "C:\Users\nifei\Downloads\DeepSort_Tutorial\.venv\Lib\site-packages\urllib3\connectionpool.py", line 466, in _make_request
    self._validate_conn(conn)
  File "C:\Users\nifei\Downloads\DeepSort_Tutorial\.venv\Lib\site-packages\urllib3\connectionpool.py", line 1095, in _validate_conn
    conn.connect()
  File "C:\Users\nifei\Downloads\DeepSort_Tutorial\.venv\Lib\site-packages\urllib3\connection.py", line 615, in connect
    self.sock = sock = self._new_conn()
                       ^^^^^^^^^^^^^^^^
  File "C:\Users\nifei\Downloads\DeepSort_Tutorial\.venv\Lib\site-packages\urllib3\connection.py", line 203, in _new_conn
    raise NameResolutionError(self.host, self, e) from e
urllib3.exceptions.NameResolutionError: <urllib3.connection.HTTPSConnection object at 0x0000029BDCBA8EC0>: Failed to resolve 'oauth2.googleapis.com' ([Errno 11001] getaddrinfo failed)

The above exception was the direct cause of the following exception:

Traceback (most recent call last):
  File "C:\Users\nifei\Downloads\DeepSort_Tutorial\.venv\Lib\site-packages\requests\adapters.py", line 667, in send
    resp = conn.urlopen(
           ^^^^^^^^^^^^^
  File "C:\Users\nifei\Downloads\DeepSort_Tutorial\.venv\Lib\site-packages\urllib3\connectionpool.py", line 843, in urlopen
    retries = retries.increment(
              ^^^^^^^^^^^^^^^^^^
  File "C:\Users\nifei\Downloads\DeepSort_Tutorial\.venv\Lib\site-packages\urllib3\util\retry.py", line 519, in increment
    raise MaxRetryError(_pool, url, reason) from reason  # type: ignore[arg-type]
    ^^^^^^^^^^^^^^^^^^^^^^^^^^^^^^^^^^^^^^^^^^^^^^^^^^^
urllib3.exceptions.MaxRetryError: HTTPSConnectionPool(host='oauth2.googleapis.com', port=443): Max retries exceeded with url: /token (Caused by NameResolutionError("<urllib3.connection.HTTPSConnection object at 0x0000029BDCBA8EC0>: Failed to resolve 'oauth2.googleapis.com' ([Errno 11001] getaddrinfo failed)"))

During handling of the above exception, another exception occurred:

Traceback (most recent call last):
  File "C:\Users\nifei\Downloads\DeepSort_Tutorial\.venv\Lib\site-packages\google\auth\transport\requests.py", line 187, in __call__
    response = self.session.request(
               ^^^^^^^^^^^^^^^^^^^^^
  File "C:\Users\nifei\Downloads\DeepSort_Tutorial\.venv\Lib\site-packages\requests\sessions.py", line 589, in request
    resp = self.send(prep, **send_kwargs)
           ^^^^^^^^^^^^^^^^^^^^^^^^^^^^^^
  File "C:\Users\nifei\Downloads\DeepSort_Tutorial\.venv\Lib\site-packages\requests\sessions.py", line 703, in send
    r = adapter.send(request, **kwargs)
        ^^^^^^^^^^^^^^^^^^^^^^^^^^^^^^^
  File "C:\Users\nifei\Downloads\DeepSort_Tutorial\.venv\Lib\site-packages\requests\adapters.py", line 700, in send
    raise ConnectionError(e, request=request)
requests.exceptions.ConnectionError: HTTPSConnectionPool(host='oauth2.googleapis.com', port=443): Max retries exceeded with url: /token (Caused by NameResolutionError("<urllib3.connection.HTTPSConnection object at 0x0000029BDCBA8EC0>: Failed to resolve 'oauth2.googleapis.com' ([Errno 11001] getaddrinfo failed)"))

The above exception was the direct cause of the following exception:

Traceback (most recent call last):
  File "C:\Users\nifei\Downloads\DeepSort_Tutorial\.venv\Lib\site-packages\grpc\_plugin_wrapping.py", line 105, in __call__
    self._metadata_plugin(
  File "C:\Users\nifei\Downloads\DeepSort_Tutorial\.venv\Lib\site-packages\google\auth\transport\grpc.py", line 95, in __call__
    callback(self._get_authorization_headers(context), None)
             ^^^^^^^^^^^^^^^^^^^^^^^^^^^^^^^^^^^^^^^^
  File "C:\Users\nifei\Downloads\DeepSort_Tutorial\.venv\Lib\site-packages\google\auth\transport\grpc.py", line 81, in _get_authorization_headers
    self._credentials.before_request(
  File "C:\Users\nifei\Downloads\DeepSort_Tutorial\.venv\Lib\site-packages\google\auth\credentials.py", line 239, in before_request
    self._blocking_refresh(request)
  File "C:\Users\nifei\Downloads\DeepSort_Tutorial\.venv\Lib\site-packages\google\auth\credentials.py", line 202, in _blocking_refresh
    self.refresh(request)
  File "C:\Users\nifei\Downloads\DeepSort_Tutorial\.venv\Lib\site-packages\google\oauth2\service_account.py", line 448, in refresh
    access_token, expiry, _ = _client.jwt_grant(
                              ^^^^^^^^^^^^^^^^^^
  File "C:\Users\nifei\Downloads\DeepSort_Tutorial\.venv\Lib\site-packages\google\oauth2\_client.py", line 298, in jwt_grant
    response_data = _token_endpoint_request(
                    ^^^^^^^^^^^^^^^^^^^^^^^^
  File "C:\Users\nifei\Downloads\DeepSort_Tutorial\.venv\Lib\site-packages\google\oauth2\_client.py", line 258, in _token_endpoint_request
    response_status_ok, response_data, retryable_error = _token_endpoint_request_no_throw(
                                                         ^^^^^^^^^^^^^^^^^^^^^^^^^^^^^^^^^
  File "C:\Users\nifei\Downloads\DeepSort_Tutorial\.venv\Lib\site-packages\google\oauth2\_client.py", line 191, in _token_endpoint_request_no_throw
    response = request(
               ^^^^^^^^
  File "C:\Users\nifei\Downloads\DeepSort_Tutorial\.venv\Lib\site-packages\google\auth\transport\requests.py", line 193, in __call__
    raise new_exc from caught_exc
google.auth.exceptions.TransportError: HTTPSConnectionPool(host='oauth2.googleapis.com', port=443): Max retries exceeded with url: /token (Caused by NameResolutionError("<urllib3.connection.HTTPSConnection object at 0x0000029BDCBA8EC0>: Failed to resolve 'oauth2.googleapis.com' ([Errno 11001] getaddrinfo failed)"))
[2024-11-07 14:12:27,003][grpc._plugin_wrapping][ERROR] - AuthMetadataPluginCallback "<google.auth.transport.grpc.AuthMetadataPlugin object at 0x0000029BDCBA9A60>" raised exception!
Traceback (most recent call last):
  File "C:\Users\nifei\Downloads\DeepSort_Tutorial\.venv\Lib\site-packages\urllib3\connection.py", line 196, in _new_conn
    sock = connection.create_connection(
           ^^^^^^^^^^^^^^^^^^^^^^^^^^^^^
  File "C:\Users\nifei\Downloads\DeepSort_Tutorial\.venv\Lib\site-packages\urllib3\util\connection.py", line 60, in create_connection
    for res in socket.getaddrinfo(host, port, family, socket.SOCK_STREAM):
               ^^^^^^^^^^^^^^^^^^^^^^^^^^^^^^^^^^^^^^^^^^^^^^^^^^^^^^^^^^
  File "C:\Users\nifei\AppData\Local\Programs\Python\Python312\Lib\socket.py", line 963, in getaddrinfo
    for res in _socket.getaddrinfo(host, port, family, type, proto, flags):
               ^^^^^^^^^^^^^^^^^^^^^^^^^^^^^^^^^^^^^^^^^^^^^^^^^^^^^^^^^^^
socket.gaierror: [Errno 11001] getaddrinfo failed

The above exception was the direct cause of the following exception:

Traceback (most recent call last):
  File "C:\Users\nifei\Downloads\DeepSort_Tutorial\.venv\Lib\site-packages\urllib3\connectionpool.py", line 789, in urlopen
    response = self._make_request(
               ^^^^^^^^^^^^^^^^^^^
  File "C:\Users\nifei\Downloads\DeepSort_Tutorial\.venv\Lib\site-packages\urllib3\connectionpool.py", line 490, in _make_request
    raise new_e
  File "C:\Users\nifei\Downloads\DeepSort_Tutorial\.venv\Lib\site-packages\urllib3\connectionpool.py", line 466, in _make_request
    self._validate_conn(conn)
  File "C:\Users\nifei\Downloads\DeepSort_Tutorial\.venv\Lib\site-packages\urllib3\connectionpool.py", line 1095, in _validate_conn
    conn.connect()
  File "C:\Users\nifei\Downloads\DeepSort_Tutorial\.venv\Lib\site-packages\urllib3\connection.py", line 615, in connect
    self.sock = sock = self._new_conn()
                       ^^^^^^^^^^^^^^^^
  File "C:\Users\nifei\Downloads\DeepSort_Tutorial\.venv\Lib\site-packages\urllib3\connection.py", line 203, in _new_conn
    raise NameResolutionError(self.host, self, e) from e
urllib3.exceptions.NameResolutionError: <urllib3.connection.HTTPSConnection object at 0x0000029BDCBE1A30>: Failed to resolve 'oauth2.googleapis.com' ([Errno 11001] getaddrinfo failed)

The above exception was the direct cause of the following exception:

Traceback (most recent call last):
  File "C:\Users\nifei\Downloads\DeepSort_Tutorial\.venv\Lib\site-packages\requests\adapters.py", line 667, in send
    resp = conn.urlopen(
           ^^^^^^^^^^^^^
  File "C:\Users\nifei\Downloads\DeepSort_Tutorial\.venv\Lib\site-packages\urllib3\connectionpool.py", line 843, in urlopen
    retries = retries.increment(
              ^^^^^^^^^^^^^^^^^^
  File "C:\Users\nifei\Downloads\DeepSort_Tutorial\.venv\Lib\site-packages\urllib3\util\retry.py", line 519, in increment
    raise MaxRetryError(_pool, url, reason) from reason  # type: ignore[arg-type]
    ^^^^^^^^^^^^^^^^^^^^^^^^^^^^^^^^^^^^^^^^^^^^^^^^^^^
urllib3.exceptions.MaxRetryError: HTTPSConnectionPool(host='oauth2.googleapis.com', port=443): Max retries exceeded with url: /token (Caused by NameResolutionError("<urllib3.connection.HTTPSConnection object at 0x0000029BDCBE1A30>: Failed to resolve 'oauth2.googleapis.com' ([Errno 11001] getaddrinfo failed)"))

During handling of the above exception, another exception occurred:

Traceback (most recent call last):
  File "C:\Users\nifei\Downloads\DeepSort_Tutorial\.venv\Lib\site-packages\google\auth\transport\requests.py", line 187, in __call__
    response = self.session.request(
               ^^^^^^^^^^^^^^^^^^^^^
  File "C:\Users\nifei\Downloads\DeepSort_Tutorial\.venv\Lib\site-packages\requests\sessions.py", line 589, in request
    resp = self.send(prep, **send_kwargs)
           ^^^^^^^^^^^^^^^^^^^^^^^^^^^^^^
  File "C:\Users\nifei\Downloads\DeepSort_Tutorial\.venv\Lib\site-packages\requests\sessions.py", line 703, in send
    r = adapter.send(request, **kwargs)
        ^^^^^^^^^^^^^^^^^^^^^^^^^^^^^^^
  File "C:\Users\nifei\Downloads\DeepSort_Tutorial\.venv\Lib\site-packages\requests\adapters.py", line 700, in send
    raise ConnectionError(e, request=request)
requests.exceptions.ConnectionError: HTTPSConnectionPool(host='oauth2.googleapis.com', port=443): Max retries exceeded with url: /token (Caused by NameResolutionError("<urllib3.connection.HTTPSConnection object at 0x0000029BDCBE1A30>: Failed to resolve 'oauth2.googleapis.com' ([Errno 11001] getaddrinfo failed)"))

The above exception was the direct cause of the following exception:

Traceback (most recent call last):
  File "C:\Users\nifei\Downloads\DeepSort_Tutorial\.venv\Lib\site-packages\grpc\_plugin_wrapping.py", line 105, in __call__
    self._metadata_plugin(
  File "C:\Users\nifei\Downloads\DeepSort_Tutorial\.venv\Lib\site-packages\google\auth\transport\grpc.py", line 95, in __call__
    callback(self._get_authorization_headers(context), None)
             ^^^^^^^^^^^^^^^^^^^^^^^^^^^^^^^^^^^^^^^^
  File "C:\Users\nifei\Downloads\DeepSort_Tutorial\.venv\Lib\site-packages\google\auth\transport\grpc.py", line 81, in _get_authorization_headers
    self._credentials.before_request(
  File "C:\Users\nifei\Downloads\DeepSort_Tutorial\.venv\Lib\site-packages\google\auth\credentials.py", line 239, in before_request
    self._blocking_refresh(request)
  File "C:\Users\nifei\Downloads\DeepSort_Tutorial\.venv\Lib\site-packages\google\auth\credentials.py", line 202, in _blocking_refresh
    self.refresh(request)
  File "C:\Users\nifei\Downloads\DeepSort_Tutorial\.venv\Lib\site-packages\google\oauth2\service_account.py", line 448, in refresh
    access_token, expiry, _ = _client.jwt_grant(
                              ^^^^^^^^^^^^^^^^^^
  File "C:\Users\nifei\Downloads\DeepSort_Tutorial\.venv\Lib\site-packages\google\oauth2\_client.py", line 298, in jwt_grant
    response_data = _token_endpoint_request(
                    ^^^^^^^^^^^^^^^^^^^^^^^^
  File "C:\Users\nifei\Downloads\DeepSort_Tutorial\.venv\Lib\site-packages\google\oauth2\_client.py", line 258, in _token_endpoint_request
    response_status_ok, response_data, retryable_error = _token_endpoint_request_no_throw(
                                                         ^^^^^^^^^^^^^^^^^^^^^^^^^^^^^^^^^
  File "C:\Users\nifei\Downloads\DeepSort_Tutorial\.venv\Lib\site-packages\google\oauth2\_client.py", line 191, in _token_endpoint_request_no_throw
    response = request(
               ^^^^^^^^
  File "C:\Users\nifei\Downloads\DeepSort_Tutorial\.venv\Lib\site-packages\google\auth\transport\requests.py", line 193, in __call__
    raise new_exc from caught_exc
google.auth.exceptions.TransportError: HTTPSConnectionPool(host='oauth2.googleapis.com', port=443): Max retries exceeded with url: /token (Caused by NameResolutionError("<urllib3.connection.HTTPSConnection object at 0x0000029BDCBE1A30>: Failed to resolve 'oauth2.googleapis.com' ([Errno 11001] getaddrinfo failed)"))
[2024-11-07 14:12:27,153][grpc._plugin_wrapping][ERROR] - AuthMetadataPluginCallback "<google.auth.transport.grpc.AuthMetadataPlugin object at 0x0000029BDCBA9A60>" raised exception!
Traceback (most recent call last):
  File "C:\Users\nifei\Downloads\DeepSort_Tutorial\.venv\Lib\site-packages\urllib3\connection.py", line 196, in _new_conn
    sock = connection.create_connection(
           ^^^^^^^^^^^^^^^^^^^^^^^^^^^^^
  File "C:\Users\nifei\Downloads\DeepSort_Tutorial\.venv\Lib\site-packages\urllib3\util\connection.py", line 60, in create_connection
    for res in socket.getaddrinfo(host, port, family, socket.SOCK_STREAM):
               ^^^^^^^^^^^^^^^^^^^^^^^^^^^^^^^^^^^^^^^^^^^^^^^^^^^^^^^^^^
  File "C:\Users\nifei\AppData\Local\Programs\Python\Python312\Lib\socket.py", line 963, in getaddrinfo
    for res in _socket.getaddrinfo(host, port, family, type, proto, flags):
               ^^^^^^^^^^^^^^^^^^^^^^^^^^^^^^^^^^^^^^^^^^^^^^^^^^^^^^^^^^^
socket.gaierror: [Errno 11001] getaddrinfo failed

The above exception was the direct cause of the following exception:

Traceback (most recent call last):
  File "C:\Users\nifei\Downloads\DeepSort_Tutorial\.venv\Lib\site-packages\urllib3\connectionpool.py", line 789, in urlopen
    response = self._make_request(
               ^^^^^^^^^^^^^^^^^^^
  File "C:\Users\nifei\Downloads\DeepSort_Tutorial\.venv\Lib\site-packages\urllib3\connectionpool.py", line 490, in _make_request
    raise new_e
  File "C:\Users\nifei\Downloads\DeepSort_Tutorial\.venv\Lib\site-packages\urllib3\connectionpool.py", line 466, in _make_request
    self._validate_conn(conn)
  File "C:\Users\nifei\Downloads\DeepSort_Tutorial\.venv\Lib\site-packages\urllib3\connectionpool.py", line 1095, in _validate_conn
    conn.connect()
  File "C:\Users\nifei\Downloads\DeepSort_Tutorial\.venv\Lib\site-packages\urllib3\connection.py", line 615, in connect
    self.sock = sock = self._new_conn()
                       ^^^^^^^^^^^^^^^^
  File "C:\Users\nifei\Downloads\DeepSort_Tutorial\.venv\Lib\site-packages\urllib3\connection.py", line 203, in _new_conn
    raise NameResolutionError(self.host, self, e) from e
urllib3.exceptions.NameResolutionError: <urllib3.connection.HTTPSConnection object at 0x0000029BDCBE1C40>: Failed to resolve 'oauth2.googleapis.com' ([Errno 11001] getaddrinfo failed)

The above exception was the direct cause of the following exception:

Traceback (most recent call last):
  File "C:\Users\nifei\Downloads\DeepSort_Tutorial\.venv\Lib\site-packages\requests\adapters.py", line 667, in send
    resp = conn.urlopen(
           ^^^^^^^^^^^^^
  File "C:\Users\nifei\Downloads\DeepSort_Tutorial\.venv\Lib\site-packages\urllib3\connectionpool.py", line 843, in urlopen
    retries = retries.increment(
              ^^^^^^^^^^^^^^^^^^
  File "C:\Users\nifei\Downloads\DeepSort_Tutorial\.venv\Lib\site-packages\urllib3\util\retry.py", line 519, in increment
    raise MaxRetryError(_pool, url, reason) from reason  # type: ignore[arg-type]
    ^^^^^^^^^^^^^^^^^^^^^^^^^^^^^^^^^^^^^^^^^^^^^^^^^^^
urllib3.exceptions.MaxRetryError: HTTPSConnectionPool(host='oauth2.googleapis.com', port=443): Max retries exceeded with url: /token (Caused by NameResolutionError("<urllib3.connection.HTTPSConnection object at 0x0000029BDCBE1C40>: Failed to resolve 'oauth2.googleapis.com' ([Errno 11001] getaddrinfo failed)"))

During handling of the above exception, another exception occurred:

Traceback (most recent call last):
  File "C:\Users\nifei\Downloads\DeepSort_Tutorial\.venv\Lib\site-packages\google\auth\transport\requests.py", line 187, in __call__
    response = self.session.request(
               ^^^^^^^^^^^^^^^^^^^^^
  File "C:\Users\nifei\Downloads\DeepSort_Tutorial\.venv\Lib\site-packages\requests\sessions.py", line 589, in request
    resp = self.send(prep, **send_kwargs)
           ^^^^^^^^^^^^^^^^^^^^^^^^^^^^^^
  File "C:\Users\nifei\Downloads\DeepSort_Tutorial\.venv\Lib\site-packages\requests\sessions.py", line 703, in send
    r = adapter.send(request, **kwargs)
        ^^^^^^^^^^^^^^^^^^^^^^^^^^^^^^^
  File "C:\Users\nifei\Downloads\DeepSort_Tutorial\.venv\Lib\site-packages\requests\adapters.py", line 700, in send
    raise ConnectionError(e, request=request)
requests.exceptions.ConnectionError: HTTPSConnectionPool(host='oauth2.googleapis.com', port=443): Max retries exceeded with url: /token (Caused by NameResolutionError("<urllib3.connection.HTTPSConnection object at 0x0000029BDCBE1C40>: Failed to resolve 'oauth2.googleapis.com' ([Errno 11001] getaddrinfo failed)"))

The above exception was the direct cause of the following exception:

Traceback (most recent call last):
  File "C:\Users\nifei\Downloads\DeepSort_Tutorial\.venv\Lib\site-packages\grpc\_plugin_wrapping.py", line 105, in __call__
    self._metadata_plugin(
  File "C:\Users\nifei\Downloads\DeepSort_Tutorial\.venv\Lib\site-packages\google\auth\transport\grpc.py", line 95, in __call__
    callback(self._get_authorization_headers(context), None)
             ^^^^^^^^^^^^^^^^^^^^^^^^^^^^^^^^^^^^^^^^
  File "C:\Users\nifei\Downloads\DeepSort_Tutorial\.venv\Lib\site-packages\google\auth\transport\grpc.py", line 81, in _get_authorization_headers
    self._credentials.before_request(
  File "C:\Users\nifei\Downloads\DeepSort_Tutorial\.venv\Lib\site-packages\google\auth\credentials.py", line 239, in before_request
    self._blocking_refresh(request)
  File "C:\Users\nifei\Downloads\DeepSort_Tutorial\.venv\Lib\site-packages\google\auth\credentials.py", line 202, in _blocking_refresh
    self.refresh(request)
  File "C:\Users\nifei\Downloads\DeepSort_Tutorial\.venv\Lib\site-packages\google\oauth2\service_account.py", line 448, in refresh
    access_token, expiry, _ = _client.jwt_grant(
                              ^^^^^^^^^^^^^^^^^^
  File "C:\Users\nifei\Downloads\DeepSort_Tutorial\.venv\Lib\site-packages\google\oauth2\_client.py", line 298, in jwt_grant
    response_data = _token_endpoint_request(
                    ^^^^^^^^^^^^^^^^^^^^^^^^
  File "C:\Users\nifei\Downloads\DeepSort_Tutorial\.venv\Lib\site-packages\google\oauth2\_client.py", line 258, in _token_endpoint_request
    response_status_ok, response_data, retryable_error = _token_endpoint_request_no_throw(
                                                         ^^^^^^^^^^^^^^^^^^^^^^^^^^^^^^^^^
  File "C:\Users\nifei\Downloads\DeepSort_Tutorial\.venv\Lib\site-packages\google\oauth2\_client.py", line 191, in _token_endpoint_request_no_throw
    response = request(
               ^^^^^^^^
  File "C:\Users\nifei\Downloads\DeepSort_Tutorial\.venv\Lib\site-packages\google\auth\transport\requests.py", line 193, in __call__
    raise new_exc from caught_exc
google.auth.exceptions.TransportError: HTTPSConnectionPool(host='oauth2.googleapis.com', port=443): Max retries exceeded with url: /token (Caused by NameResolutionError("<urllib3.connection.HTTPSConnection object at 0x0000029BDCBE1C40>: Failed to resolve 'oauth2.googleapis.com' ([Errno 11001] getaddrinfo failed)"))
[2024-11-07 14:12:27,203][grpc._plugin_wrapping][ERROR] - AuthMetadataPluginCallback "<google.auth.transport.grpc.AuthMetadataPlugin object at 0x0000029BDCBA9A60>" raised exception!
Traceback (most recent call last):
  File "C:\Users\nifei\Downloads\DeepSort_Tutorial\.venv\Lib\site-packages\urllib3\connection.py", line 196, in _new_conn
    sock = connection.create_connection(
           ^^^^^^^^^^^^^^^^^^^^^^^^^^^^^
  File "C:\Users\nifei\Downloads\DeepSort_Tutorial\.venv\Lib\site-packages\urllib3\util\connection.py", line 60, in create_connection
    for res in socket.getaddrinfo(host, port, family, socket.SOCK_STREAM):
               ^^^^^^^^^^^^^^^^^^^^^^^^^^^^^^^^^^^^^^^^^^^^^^^^^^^^^^^^^^
  File "C:\Users\nifei\AppData\Local\Programs\Python\Python312\Lib\socket.py", line 963, in getaddrinfo
    for res in _socket.getaddrinfo(host, port, family, type, proto, flags):
               ^^^^^^^^^^^^^^^^^^^^^^^^^^^^^^^^^^^^^^^^^^^^^^^^^^^^^^^^^^^
socket.gaierror: [Errno 11001] getaddrinfo failed

The above exception was the direct cause of the following exception:

Traceback (most recent call last):
  File "C:\Users\nifei\Downloads\DeepSort_Tutorial\.venv\Lib\site-packages\urllib3\connectionpool.py", line 789, in urlopen
    response = self._make_request(
               ^^^^^^^^^^^^^^^^^^^
  File "C:\Users\nifei\Downloads\DeepSort_Tutorial\.venv\Lib\site-packages\urllib3\connectionpool.py", line 490, in _make_request
    raise new_e
  File "C:\Users\nifei\Downloads\DeepSort_Tutorial\.venv\Lib\site-packages\urllib3\connectionpool.py", line 466, in _make_request
    self._validate_conn(conn)
  File "C:\Users\nifei\Downloads\DeepSort_Tutorial\.venv\Lib\site-packages\urllib3\connectionpool.py", line 1095, in _validate_conn
    conn.connect()
  File "C:\Users\nifei\Downloads\DeepSort_Tutorial\.venv\Lib\site-packages\urllib3\connection.py", line 615, in connect
    self.sock = sock = self._new_conn()
                       ^^^^^^^^^^^^^^^^
  File "C:\Users\nifei\Downloads\DeepSort_Tutorial\.venv\Lib\site-packages\urllib3\connection.py", line 203, in _new_conn
    raise NameResolutionError(self.host, self, e) from e
urllib3.exceptions.NameResolutionError: <urllib3.connection.HTTPSConnection object at 0x0000029BDCBE2A50>: Failed to resolve 'oauth2.googleapis.com' ([Errno 11001] getaddrinfo failed)

The above exception was the direct cause of the following exception:

Traceback (most recent call last):
  File "C:\Users\nifei\Downloads\DeepSort_Tutorial\.venv\Lib\site-packages\requests\adapters.py", line 667, in send
    resp = conn.urlopen(
           ^^^^^^^^^^^^^
  File "C:\Users\nifei\Downloads\DeepSort_Tutorial\.venv\Lib\site-packages\urllib3\connectionpool.py", line 843, in urlopen
    retries = retries.increment(
              ^^^^^^^^^^^^^^^^^^
  File "C:\Users\nifei\Downloads\DeepSort_Tutorial\.venv\Lib\site-packages\urllib3\util\retry.py", line 519, in increment
    raise MaxRetryError(_pool, url, reason) from reason  # type: ignore[arg-type]
    ^^^^^^^^^^^^^^^^^^^^^^^^^^^^^^^^^^^^^^^^^^^^^^^^^^^
urllib3.exceptions.MaxRetryError: HTTPSConnectionPool(host='oauth2.googleapis.com', port=443): Max retries exceeded with url: /token (Caused by NameResolutionError("<urllib3.connection.HTTPSConnection object at 0x0000029BDCBE2A50>: Failed to resolve 'oauth2.googleapis.com' ([Errno 11001] getaddrinfo failed)"))

During handling of the above exception, another exception occurred:

Traceback (most recent call last):
  File "C:\Users\nifei\Downloads\DeepSort_Tutorial\.venv\Lib\site-packages\google\auth\transport\requests.py", line 187, in __call__
    response = self.session.request(
               ^^^^^^^^^^^^^^^^^^^^^
  File "C:\Users\nifei\Downloads\DeepSort_Tutorial\.venv\Lib\site-packages\requests\sessions.py", line 589, in request
    resp = self.send(prep, **send_kwargs)
           ^^^^^^^^^^^^^^^^^^^^^^^^^^^^^^
  File "C:\Users\nifei\Downloads\DeepSort_Tutorial\.venv\Lib\site-packages\requests\sessions.py", line 703, in send
    r = adapter.send(request, **kwargs)
        ^^^^^^^^^^^^^^^^^^^^^^^^^^^^^^^
  File "C:\Users\nifei\Downloads\DeepSort_Tutorial\.venv\Lib\site-packages\requests\adapters.py", line 700, in send
    raise ConnectionError(e, request=request)
requests.exceptions.ConnectionError: HTTPSConnectionPool(host='oauth2.googleapis.com', port=443): Max retries exceeded with url: /token (Caused by NameResolutionError("<urllib3.connection.HTTPSConnection object at 0x0000029BDCBE2A50>: Failed to resolve 'oauth2.googleapis.com' ([Errno 11001] getaddrinfo failed)"))

The above exception was the direct cause of the following exception:

Traceback (most recent call last):
  File "C:\Users\nifei\Downloads\DeepSort_Tutorial\.venv\Lib\site-packages\grpc\_plugin_wrapping.py", line 105, in __call__
    self._metadata_plugin(
  File "C:\Users\nifei\Downloads\DeepSort_Tutorial\.venv\Lib\site-packages\google\auth\transport\grpc.py", line 95, in __call__
    callback(self._get_authorization_headers(context), None)
             ^^^^^^^^^^^^^^^^^^^^^^^^^^^^^^^^^^^^^^^^
  File "C:\Users\nifei\Downloads\DeepSort_Tutorial\.venv\Lib\site-packages\google\auth\transport\grpc.py", line 81, in _get_authorization_headers
    self._credentials.before_request(
  File "C:\Users\nifei\Downloads\DeepSort_Tutorial\.venv\Lib\site-packages\google\auth\credentials.py", line 239, in before_request
    self._blocking_refresh(request)
  File "C:\Users\nifei\Downloads\DeepSort_Tutorial\.venv\Lib\site-packages\google\auth\credentials.py", line 202, in _blocking_refresh
    self.refresh(request)
  File "C:\Users\nifei\Downloads\DeepSort_Tutorial\.venv\Lib\site-packages\google\oauth2\service_account.py", line 448, in refresh
    access_token, expiry, _ = _client.jwt_grant(
                              ^^^^^^^^^^^^^^^^^^
  File "C:\Users\nifei\Downloads\DeepSort_Tutorial\.venv\Lib\site-packages\google\oauth2\_client.py", line 298, in jwt_grant
    response_data = _token_endpoint_request(
                    ^^^^^^^^^^^^^^^^^^^^^^^^
  File "C:\Users\nifei\Downloads\DeepSort_Tutorial\.venv\Lib\site-packages\google\oauth2\_client.py", line 258, in _token_endpoint_request
    response_status_ok, response_data, retryable_error = _token_endpoint_request_no_throw(
                                                         ^^^^^^^^^^^^^^^^^^^^^^^^^^^^^^^^^
  File "C:\Users\nifei\Downloads\DeepSort_Tutorial\.venv\Lib\site-packages\google\oauth2\_client.py", line 191, in _token_endpoint_request_no_throw
    response = request(
               ^^^^^^^^
  File "C:\Users\nifei\Downloads\DeepSort_Tutorial\.venv\Lib\site-packages\google\auth\transport\requests.py", line 193, in __call__
    raise new_exc from caught_exc
google.auth.exceptions.TransportError: HTTPSConnectionPool(host='oauth2.googleapis.com', port=443): Max retries exceeded with url: /token (Caused by NameResolutionError("<urllib3.connection.HTTPSConnection object at 0x0000029BDCBE2A50>: Failed to resolve 'oauth2.googleapis.com' ([Errno 11001] getaddrinfo failed)"))
[2024-11-07 14:12:27,290][grpc._plugin_wrapping][ERROR] - AuthMetadataPluginCallback "<google.auth.transport.grpc.AuthMetadataPlugin object at 0x0000029BDCBA9A60>" raised exception!
Traceback (most recent call last):
  File "C:\Users\nifei\Downloads\DeepSort_Tutorial\.venv\Lib\site-packages\urllib3\connection.py", line 196, in _new_conn
    sock = connection.create_connection(
           ^^^^^^^^^^^^^^^^^^^^^^^^^^^^^
  File "C:\Users\nifei\Downloads\DeepSort_Tutorial\.venv\Lib\site-packages\urllib3\util\connection.py", line 60, in create_connection
    for res in socket.getaddrinfo(host, port, family, socket.SOCK_STREAM):
               ^^^^^^^^^^^^^^^^^^^^^^^^^^^^^^^^^^^^^^^^^^^^^^^^^^^^^^^^^^
  File "C:\Users\nifei\AppData\Local\Programs\Python\Python312\Lib\socket.py", line 963, in getaddrinfo
    for res in _socket.getaddrinfo(host, port, family, type, proto, flags):
               ^^^^^^^^^^^^^^^^^^^^^^^^^^^^^^^^^^^^^^^^^^^^^^^^^^^^^^^^^^^
socket.gaierror: [Errno 11001] getaddrinfo failed

The above exception was the direct cause of the following exception:

Traceback (most recent call last):
  File "C:\Users\nifei\Downloads\DeepSort_Tutorial\.venv\Lib\site-packages\urllib3\connectionpool.py", line 789, in urlopen
    response = self._make_request(
               ^^^^^^^^^^^^^^^^^^^
  File "C:\Users\nifei\Downloads\DeepSort_Tutorial\.venv\Lib\site-packages\urllib3\connectionpool.py", line 490, in _make_request
    raise new_e
  File "C:\Users\nifei\Downloads\DeepSort_Tutorial\.venv\Lib\site-packages\urllib3\connectionpool.py", line 466, in _make_request
    self._validate_conn(conn)
  File "C:\Users\nifei\Downloads\DeepSort_Tutorial\.venv\Lib\site-packages\urllib3\connectionpool.py", line 1095, in _validate_conn
    conn.connect()
  File "C:\Users\nifei\Downloads\DeepSort_Tutorial\.venv\Lib\site-packages\urllib3\connection.py", line 615, in connect
    self.sock = sock = self._new_conn()
                       ^^^^^^^^^^^^^^^^
  File "C:\Users\nifei\Downloads\DeepSort_Tutorial\.venv\Lib\site-packages\urllib3\connection.py", line 203, in _new_conn
    raise NameResolutionError(self.host, self, e) from e
urllib3.exceptions.NameResolutionError: <urllib3.connection.HTTPSConnection object at 0x0000029BDC6DA9F0>: Failed to resolve 'oauth2.googleapis.com' ([Errno 11001] getaddrinfo failed)

The above exception was the direct cause of the following exception:

Traceback (most recent call last):
  File "C:\Users\nifei\Downloads\DeepSort_Tutorial\.venv\Lib\site-packages\requests\adapters.py", line 667, in send
    resp = conn.urlopen(
           ^^^^^^^^^^^^^
  File "C:\Users\nifei\Downloads\DeepSort_Tutorial\.venv\Lib\site-packages\urllib3\connectionpool.py", line 843, in urlopen
    retries = retries.increment(
              ^^^^^^^^^^^^^^^^^^
  File "C:\Users\nifei\Downloads\DeepSort_Tutorial\.venv\Lib\site-packages\urllib3\util\retry.py", line 519, in increment
    raise MaxRetryError(_pool, url, reason) from reason  # type: ignore[arg-type]
    ^^^^^^^^^^^^^^^^^^^^^^^^^^^^^^^^^^^^^^^^^^^^^^^^^^^
urllib3.exceptions.MaxRetryError: HTTPSConnectionPool(host='oauth2.googleapis.com', port=443): Max retries exceeded with url: /token (Caused by NameResolutionError("<urllib3.connection.HTTPSConnection object at 0x0000029BDC6DA9F0>: Failed to resolve 'oauth2.googleapis.com' ([Errno 11001] getaddrinfo failed)"))

During handling of the above exception, another exception occurred:

Traceback (most recent call last):
  File "C:\Users\nifei\Downloads\DeepSort_Tutorial\.venv\Lib\site-packages\google\auth\transport\requests.py", line 187, in __call__
    response = self.session.request(
               ^^^^^^^^^^^^^^^^^^^^^
  File "C:\Users\nifei\Downloads\DeepSort_Tutorial\.venv\Lib\site-packages\requests\sessions.py", line 589, in request
    resp = self.send(prep, **send_kwargs)
           ^^^^^^^^^^^^^^^^^^^^^^^^^^^^^^
  File "C:\Users\nifei\Downloads\DeepSort_Tutorial\.venv\Lib\site-packages\requests\sessions.py", line 703, in send
    r = adapter.send(request, **kwargs)
        ^^^^^^^^^^^^^^^^^^^^^^^^^^^^^^^
  File "C:\Users\nifei\Downloads\DeepSort_Tutorial\.venv\Lib\site-packages\requests\adapters.py", line 700, in send
    raise ConnectionError(e, request=request)
requests.exceptions.ConnectionError: HTTPSConnectionPool(host='oauth2.googleapis.com', port=443): Max retries exceeded with url: /token (Caused by NameResolutionError("<urllib3.connection.HTTPSConnection object at 0x0000029BDC6DA9F0>: Failed to resolve 'oauth2.googleapis.com' ([Errno 11001] getaddrinfo failed)"))

The above exception was the direct cause of the following exception:

Traceback (most recent call last):
  File "C:\Users\nifei\Downloads\DeepSort_Tutorial\.venv\Lib\site-packages\grpc\_plugin_wrapping.py", line 105, in __call__
    self._metadata_plugin(
  File "C:\Users\nifei\Downloads\DeepSort_Tutorial\.venv\Lib\site-packages\google\auth\transport\grpc.py", line 95, in __call__
    callback(self._get_authorization_headers(context), None)
             ^^^^^^^^^^^^^^^^^^^^^^^^^^^^^^^^^^^^^^^^
  File "C:\Users\nifei\Downloads\DeepSort_Tutorial\.venv\Lib\site-packages\google\auth\transport\grpc.py", line 81, in _get_authorization_headers
    self._credentials.before_request(
  File "C:\Users\nifei\Downloads\DeepSort_Tutorial\.venv\Lib\site-packages\google\auth\credentials.py", line 239, in before_request
    self._blocking_refresh(request)
  File "C:\Users\nifei\Downloads\DeepSort_Tutorial\.venv\Lib\site-packages\google\auth\credentials.py", line 202, in _blocking_refresh
    self.refresh(request)
  File "C:\Users\nifei\Downloads\DeepSort_Tutorial\.venv\Lib\site-packages\google\oauth2\service_account.py", line 448, in refresh
    access_token, expiry, _ = _client.jwt_grant(
                              ^^^^^^^^^^^^^^^^^^
  File "C:\Users\nifei\Downloads\DeepSort_Tutorial\.venv\Lib\site-packages\google\oauth2\_client.py", line 298, in jwt_grant
    response_data = _token_endpoint_request(
                    ^^^^^^^^^^^^^^^^^^^^^^^^
  File "C:\Users\nifei\Downloads\DeepSort_Tutorial\.venv\Lib\site-packages\google\oauth2\_client.py", line 258, in _token_endpoint_request
    response_status_ok, response_data, retryable_error = _token_endpoint_request_no_throw(
                                                         ^^^^^^^^^^^^^^^^^^^^^^^^^^^^^^^^^
  File "C:\Users\nifei\Downloads\DeepSort_Tutorial\.venv\Lib\site-packages\google\oauth2\_client.py", line 191, in _token_endpoint_request_no_throw
    response = request(
               ^^^^^^^^
  File "C:\Users\nifei\Downloads\DeepSort_Tutorial\.venv\Lib\site-packages\google\auth\transport\requests.py", line 193, in __call__
    raise new_exc from caught_exc
google.auth.exceptions.TransportError: HTTPSConnectionPool(host='oauth2.googleapis.com', port=443): Max retries exceeded with url: /token (Caused by NameResolutionError("<urllib3.connection.HTTPSConnection object at 0x0000029BDC6DA9F0>: Failed to resolve 'oauth2.googleapis.com' ([Errno 11001] getaddrinfo failed)"))
[2024-11-07 14:12:27,339][grpc._plugin_wrapping][ERROR] - AuthMetadataPluginCallback "<google.auth.transport.grpc.AuthMetadataPlugin object at 0x0000029BDCBA9A60>" raised exception!
Traceback (most recent call last):
  File "C:\Users\nifei\Downloads\DeepSort_Tutorial\.venv\Lib\site-packages\urllib3\connection.py", line 196, in _new_conn
    sock = connection.create_connection(
           ^^^^^^^^^^^^^^^^^^^^^^^^^^^^^
  File "C:\Users\nifei\Downloads\DeepSort_Tutorial\.venv\Lib\site-packages\urllib3\util\connection.py", line 60, in create_connection
    for res in socket.getaddrinfo(host, port, family, socket.SOCK_STREAM):
               ^^^^^^^^^^^^^^^^^^^^^^^^^^^^^^^^^^^^^^^^^^^^^^^^^^^^^^^^^^
  File "C:\Users\nifei\AppData\Local\Programs\Python\Python312\Lib\socket.py", line 963, in getaddrinfo
    for res in _socket.getaddrinfo(host, port, family, type, proto, flags):
               ^^^^^^^^^^^^^^^^^^^^^^^^^^^^^^^^^^^^^^^^^^^^^^^^^^^^^^^^^^^
socket.gaierror: [Errno 11001] getaddrinfo failed

The above exception was the direct cause of the following exception:

Traceback (most recent call last):
  File "C:\Users\nifei\Downloads\DeepSort_Tutorial\.venv\Lib\site-packages\urllib3\connectionpool.py", line 789, in urlopen
    response = self._make_request(
               ^^^^^^^^^^^^^^^^^^^
  File "C:\Users\nifei\Downloads\DeepSort_Tutorial\.venv\Lib\site-packages\urllib3\connectionpool.py", line 490, in _make_request
    raise new_e
  File "C:\Users\nifei\Downloads\DeepSort_Tutorial\.venv\Lib\site-packages\urllib3\connectionpool.py", line 466, in _make_request
    self._validate_conn(conn)
  File "C:\Users\nifei\Downloads\DeepSort_Tutorial\.venv\Lib\site-packages\urllib3\connectionpool.py", line 1095, in _validate_conn
    conn.connect()
  File "C:\Users\nifei\Downloads\DeepSort_Tutorial\.venv\Lib\site-packages\urllib3\connection.py", line 615, in connect
    self.sock = sock = self._new_conn()
                       ^^^^^^^^^^^^^^^^
  File "C:\Users\nifei\Downloads\DeepSort_Tutorial\.venv\Lib\site-packages\urllib3\connection.py", line 203, in _new_conn
    raise NameResolutionError(self.host, self, e) from e
urllib3.exceptions.NameResolutionError: <urllib3.connection.HTTPSConnection object at 0x0000029BDC6E9A60>: Failed to resolve 'oauth2.googleapis.com' ([Errno 11001] getaddrinfo failed)

The above exception was the direct cause of the following exception:

Traceback (most recent call last):
  File "C:\Users\nifei\Downloads\DeepSort_Tutorial\.venv\Lib\site-packages\requests\adapters.py", line 667, in send
    resp = conn.urlopen(
           ^^^^^^^^^^^^^
  File "C:\Users\nifei\Downloads\DeepSort_Tutorial\.venv\Lib\site-packages\urllib3\connectionpool.py", line 843, in urlopen
    retries = retries.increment(
              ^^^^^^^^^^^^^^^^^^
  File "C:\Users\nifei\Downloads\DeepSort_Tutorial\.venv\Lib\site-packages\urllib3\util\retry.py", line 519, in increment
    raise MaxRetryError(_pool, url, reason) from reason  # type: ignore[arg-type]
    ^^^^^^^^^^^^^^^^^^^^^^^^^^^^^^^^^^^^^^^^^^^^^^^^^^^
urllib3.exceptions.MaxRetryError: HTTPSConnectionPool(host='oauth2.googleapis.com', port=443): Max retries exceeded with url: /token (Caused by NameResolutionError("<urllib3.connection.HTTPSConnection object at 0x0000029BDC6E9A60>: Failed to resolve 'oauth2.googleapis.com' ([Errno 11001] getaddrinfo failed)"))

During handling of the above exception, another exception occurred:

Traceback (most recent call last):
  File "C:\Users\nifei\Downloads\DeepSort_Tutorial\.venv\Lib\site-packages\google\auth\transport\requests.py", line 187, in __call__
    response = self.session.request(
               ^^^^^^^^^^^^^^^^^^^^^
  File "C:\Users\nifei\Downloads\DeepSort_Tutorial\.venv\Lib\site-packages\requests\sessions.py", line 589, in request
    resp = self.send(prep, **send_kwargs)
           ^^^^^^^^^^^^^^^^^^^^^^^^^^^^^^
  File "C:\Users\nifei\Downloads\DeepSort_Tutorial\.venv\Lib\site-packages\requests\sessions.py", line 703, in send
    r = adapter.send(request, **kwargs)
        ^^^^^^^^^^^^^^^^^^^^^^^^^^^^^^^
  File "C:\Users\nifei\Downloads\DeepSort_Tutorial\.venv\Lib\site-packages\requests\adapters.py", line 700, in send
    raise ConnectionError(e, request=request)
requests.exceptions.ConnectionError: HTTPSConnectionPool(host='oauth2.googleapis.com', port=443): Max retries exceeded with url: /token (Caused by NameResolutionError("<urllib3.connection.HTTPSConnection object at 0x0000029BDC6E9A60>: Failed to resolve 'oauth2.googleapis.com' ([Errno 11001] getaddrinfo failed)"))

The above exception was the direct cause of the following exception:

Traceback (most recent call last):
  File "C:\Users\nifei\Downloads\DeepSort_Tutorial\.venv\Lib\site-packages\grpc\_plugin_wrapping.py", line 105, in __call__
    self._metadata_plugin(
  File "C:\Users\nifei\Downloads\DeepSort_Tutorial\.venv\Lib\site-packages\google\auth\transport\grpc.py", line 95, in __call__
    callback(self._get_authorization_headers(context), None)
             ^^^^^^^^^^^^^^^^^^^^^^^^^^^^^^^^^^^^^^^^
  File "C:\Users\nifei\Downloads\DeepSort_Tutorial\.venv\Lib\site-packages\google\auth\transport\grpc.py", line 81, in _get_authorization_headers
    self._credentials.before_request(
  File "C:\Users\nifei\Downloads\DeepSort_Tutorial\.venv\Lib\site-packages\google\auth\credentials.py", line 239, in before_request
    self._blocking_refresh(request)
  File "C:\Users\nifei\Downloads\DeepSort_Tutorial\.venv\Lib\site-packages\google\auth\credentials.py", line 202, in _blocking_refresh
    self.refresh(request)
  File "C:\Users\nifei\Downloads\DeepSort_Tutorial\.venv\Lib\site-packages\google\oauth2\service_account.py", line 448, in refresh
    access_token, expiry, _ = _client.jwt_grant(
                              ^^^^^^^^^^^^^^^^^^
  File "C:\Users\nifei\Downloads\DeepSort_Tutorial\.venv\Lib\site-packages\google\oauth2\_client.py", line 298, in jwt_grant
    response_data = _token_endpoint_request(
                    ^^^^^^^^^^^^^^^^^^^^^^^^
  File "C:\Users\nifei\Downloads\DeepSort_Tutorial\.venv\Lib\site-packages\google\oauth2\_client.py", line 258, in _token_endpoint_request
    response_status_ok, response_data, retryable_error = _token_endpoint_request_no_throw(
                                                         ^^^^^^^^^^^^^^^^^^^^^^^^^^^^^^^^^
  File "C:\Users\nifei\Downloads\DeepSort_Tutorial\.venv\Lib\site-packages\google\oauth2\_client.py", line 191, in _token_endpoint_request_no_throw
    response = request(
               ^^^^^^^^
  File "C:\Users\nifei\Downloads\DeepSort_Tutorial\.venv\Lib\site-packages\google\auth\transport\requests.py", line 193, in __call__
    raise new_exc from caught_exc
google.auth.exceptions.TransportError: HTTPSConnectionPool(host='oauth2.googleapis.com', port=443): Max retries exceeded with url: /token (Caused by NameResolutionError("<urllib3.connection.HTTPSConnection object at 0x0000029BDC6E9A60>: Failed to resolve 'oauth2.googleapis.com' ([Errno 11001] getaddrinfo failed)"))
[2024-11-07 14:12:27,562][grpc._plugin_wrapping][ERROR] - AuthMetadataPluginCallback "<google.auth.transport.grpc.AuthMetadataPlugin object at 0x0000029BDCBA9A60>" raised exception!
Traceback (most recent call last):
  File "C:\Users\nifei\Downloads\DeepSort_Tutorial\.venv\Lib\site-packages\urllib3\connection.py", line 196, in _new_conn
    sock = connection.create_connection(
           ^^^^^^^^^^^^^^^^^^^^^^^^^^^^^
  File "C:\Users\nifei\Downloads\DeepSort_Tutorial\.venv\Lib\site-packages\urllib3\util\connection.py", line 60, in create_connection
    for res in socket.getaddrinfo(host, port, family, socket.SOCK_STREAM):
               ^^^^^^^^^^^^^^^^^^^^^^^^^^^^^^^^^^^^^^^^^^^^^^^^^^^^^^^^^^
  File "C:\Users\nifei\AppData\Local\Programs\Python\Python312\Lib\socket.py", line 963, in getaddrinfo
    for res in _socket.getaddrinfo(host, port, family, type, proto, flags):
               ^^^^^^^^^^^^^^^^^^^^^^^^^^^^^^^^^^^^^^^^^^^^^^^^^^^^^^^^^^^
socket.gaierror: [Errno 11001] getaddrinfo failed

The above exception was the direct cause of the following exception:

Traceback (most recent call last):
  File "C:\Users\nifei\Downloads\DeepSort_Tutorial\.venv\Lib\site-packages\urllib3\connectionpool.py", line 789, in urlopen
    response = self._make_request(
               ^^^^^^^^^^^^^^^^^^^
  File "C:\Users\nifei\Downloads\DeepSort_Tutorial\.venv\Lib\site-packages\urllib3\connectionpool.py", line 490, in _make_request
    raise new_e
  File "C:\Users\nifei\Downloads\DeepSort_Tutorial\.venv\Lib\site-packages\urllib3\connectionpool.py", line 466, in _make_request
    self._validate_conn(conn)
  File "C:\Users\nifei\Downloads\DeepSort_Tutorial\.venv\Lib\site-packages\urllib3\connectionpool.py", line 1095, in _validate_conn
    conn.connect()
  File "C:\Users\nifei\Downloads\DeepSort_Tutorial\.venv\Lib\site-packages\urllib3\connection.py", line 615, in connect
    self.sock = sock = self._new_conn()
                       ^^^^^^^^^^^^^^^^
  File "C:\Users\nifei\Downloads\DeepSort_Tutorial\.venv\Lib\site-packages\urllib3\connection.py", line 203, in _new_conn
    raise NameResolutionError(self.host, self, e) from e
urllib3.exceptions.NameResolutionError: <urllib3.connection.HTTPSConnection object at 0x0000029BDCBE2360>: Failed to resolve 'oauth2.googleapis.com' ([Errno 11001] getaddrinfo failed)

The above exception was the direct cause of the following exception:

Traceback (most recent call last):
  File "C:\Users\nifei\Downloads\DeepSort_Tutorial\.venv\Lib\site-packages\requests\adapters.py", line 667, in send
    resp = conn.urlopen(
           ^^^^^^^^^^^^^
  File "C:\Users\nifei\Downloads\DeepSort_Tutorial\.venv\Lib\site-packages\urllib3\connectionpool.py", line 843, in urlopen
    retries = retries.increment(
              ^^^^^^^^^^^^^^^^^^
  File "C:\Users\nifei\Downloads\DeepSort_Tutorial\.venv\Lib\site-packages\urllib3\util\retry.py", line 519, in increment
    raise MaxRetryError(_pool, url, reason) from reason  # type: ignore[arg-type]
    ^^^^^^^^^^^^^^^^^^^^^^^^^^^^^^^^^^^^^^^^^^^^^^^^^^^
urllib3.exceptions.MaxRetryError: HTTPSConnectionPool(host='oauth2.googleapis.com', port=443): Max retries exceeded with url: /token (Caused by NameResolutionError("<urllib3.connection.HTTPSConnection object at 0x0000029BDCBE2360>: Failed to resolve 'oauth2.googleapis.com' ([Errno 11001] getaddrinfo failed)"))

During handling of the above exception, another exception occurred:

Traceback (most recent call last):
  File "C:\Users\nifei\Downloads\DeepSort_Tutorial\.venv\Lib\site-packages\google\auth\transport\requests.py", line 187, in __call__
    response = self.session.request(
               ^^^^^^^^^^^^^^^^^^^^^
  File "C:\Users\nifei\Downloads\DeepSort_Tutorial\.venv\Lib\site-packages\requests\sessions.py", line 589, in request
    resp = self.send(prep, **send_kwargs)
           ^^^^^^^^^^^^^^^^^^^^^^^^^^^^^^
  File "C:\Users\nifei\Downloads\DeepSort_Tutorial\.venv\Lib\site-packages\requests\sessions.py", line 703, in send
    r = adapter.send(request, **kwargs)
        ^^^^^^^^^^^^^^^^^^^^^^^^^^^^^^^
  File "C:\Users\nifei\Downloads\DeepSort_Tutorial\.venv\Lib\site-packages\requests\adapters.py", line 700, in send
    raise ConnectionError(e, request=request)
requests.exceptions.ConnectionError: HTTPSConnectionPool(host='oauth2.googleapis.com', port=443): Max retries exceeded with url: /token (Caused by NameResolutionError("<urllib3.connection.HTTPSConnection object at 0x0000029BDCBE2360>: Failed to resolve 'oauth2.googleapis.com' ([Errno 11001] getaddrinfo failed)"))

The above exception was the direct cause of the following exception:

Traceback (most recent call last):
  File "C:\Users\nifei\Downloads\DeepSort_Tutorial\.venv\Lib\site-packages\grpc\_plugin_wrapping.py", line 105, in __call__
    self._metadata_plugin(
  File "C:\Users\nifei\Downloads\DeepSort_Tutorial\.venv\Lib\site-packages\google\auth\transport\grpc.py", line 95, in __call__
    callback(self._get_authorization_headers(context), None)
             ^^^^^^^^^^^^^^^^^^^^^^^^^^^^^^^^^^^^^^^^
  File "C:\Users\nifei\Downloads\DeepSort_Tutorial\.venv\Lib\site-packages\google\auth\transport\grpc.py", line 81, in _get_authorization_headers
    self._credentials.before_request(
  File "C:\Users\nifei\Downloads\DeepSort_Tutorial\.venv\Lib\site-packages\google\auth\credentials.py", line 239, in before_request
    self._blocking_refresh(request)
  File "C:\Users\nifei\Downloads\DeepSort_Tutorial\.venv\Lib\site-packages\google\auth\credentials.py", line 202, in _blocking_refresh
    self.refresh(request)
  File "C:\Users\nifei\Downloads\DeepSort_Tutorial\.venv\Lib\site-packages\google\oauth2\service_account.py", line 448, in refresh
    access_token, expiry, _ = _client.jwt_grant(
                              ^^^^^^^^^^^^^^^^^^
  File "C:\Users\nifei\Downloads\DeepSort_Tutorial\.venv\Lib\site-packages\google\oauth2\_client.py", line 298, in jwt_grant
    response_data = _token_endpoint_request(
                    ^^^^^^^^^^^^^^^^^^^^^^^^
  File "C:\Users\nifei\Downloads\DeepSort_Tutorial\.venv\Lib\site-packages\google\oauth2\_client.py", line 258, in _token_endpoint_request
    response_status_ok, response_data, retryable_error = _token_endpoint_request_no_throw(
                                                         ^^^^^^^^^^^^^^^^^^^^^^^^^^^^^^^^^
  File "C:\Users\nifei\Downloads\DeepSort_Tutorial\.venv\Lib\site-packages\google\oauth2\_client.py", line 191, in _token_endpoint_request_no_throw
    response = request(
               ^^^^^^^^
  File "C:\Users\nifei\Downloads\DeepSort_Tutorial\.venv\Lib\site-packages\google\auth\transport\requests.py", line 193, in __call__
    raise new_exc from caught_exc
google.auth.exceptions.TransportError: HTTPSConnectionPool(host='oauth2.googleapis.com', port=443): Max retries exceeded with url: /token (Caused by NameResolutionError("<urllib3.connection.HTTPSConnection object at 0x0000029BDCBE2360>: Failed to resolve 'oauth2.googleapis.com' ([Errno 11001] getaddrinfo failed)"))
[2024-11-07 14:12:27,921][grpc._plugin_wrapping][ERROR] - AuthMetadataPluginCallback "<google.auth.transport.grpc.AuthMetadataPlugin object at 0x0000029BDCBA9A60>" raised exception!
Traceback (most recent call last):
  File "C:\Users\nifei\Downloads\DeepSort_Tutorial\.venv\Lib\site-packages\urllib3\connection.py", line 196, in _new_conn
    sock = connection.create_connection(
           ^^^^^^^^^^^^^^^^^^^^^^^^^^^^^
  File "C:\Users\nifei\Downloads\DeepSort_Tutorial\.venv\Lib\site-packages\urllib3\util\connection.py", line 60, in create_connection
    for res in socket.getaddrinfo(host, port, family, socket.SOCK_STREAM):
               ^^^^^^^^^^^^^^^^^^^^^^^^^^^^^^^^^^^^^^^^^^^^^^^^^^^^^^^^^^
  File "C:\Users\nifei\AppData\Local\Programs\Python\Python312\Lib\socket.py", line 963, in getaddrinfo
    for res in _socket.getaddrinfo(host, port, family, type, proto, flags):
               ^^^^^^^^^^^^^^^^^^^^^^^^^^^^^^^^^^^^^^^^^^^^^^^^^^^^^^^^^^^
socket.gaierror: [Errno 11001] getaddrinfo failed

The above exception was the direct cause of the following exception:

Traceback (most recent call last):
  File "C:\Users\nifei\Downloads\DeepSort_Tutorial\.venv\Lib\site-packages\urllib3\connectionpool.py", line 789, in urlopen
    response = self._make_request(
               ^^^^^^^^^^^^^^^^^^^
  File "C:\Users\nifei\Downloads\DeepSort_Tutorial\.venv\Lib\site-packages\urllib3\connectionpool.py", line 490, in _make_request
    raise new_e
  File "C:\Users\nifei\Downloads\DeepSort_Tutorial\.venv\Lib\site-packages\urllib3\connectionpool.py", line 466, in _make_request
    self._validate_conn(conn)
  File "C:\Users\nifei\Downloads\DeepSort_Tutorial\.venv\Lib\site-packages\urllib3\connectionpool.py", line 1095, in _validate_conn
    conn.connect()
  File "C:\Users\nifei\Downloads\DeepSort_Tutorial\.venv\Lib\site-packages\urllib3\connection.py", line 615, in connect
    self.sock = sock = self._new_conn()
                       ^^^^^^^^^^^^^^^^
  File "C:\Users\nifei\Downloads\DeepSort_Tutorial\.venv\Lib\site-packages\urllib3\connection.py", line 203, in _new_conn
    raise NameResolutionError(self.host, self, e) from e
urllib3.exceptions.NameResolutionError: <urllib3.connection.HTTPSConnection object at 0x0000029BDCBA8770>: Failed to resolve 'oauth2.googleapis.com' ([Errno 11001] getaddrinfo failed)

The above exception was the direct cause of the following exception:

Traceback (most recent call last):
  File "C:\Users\nifei\Downloads\DeepSort_Tutorial\.venv\Lib\site-packages\requests\adapters.py", line 667, in send
    resp = conn.urlopen(
           ^^^^^^^^^^^^^
  File "C:\Users\nifei\Downloads\DeepSort_Tutorial\.venv\Lib\site-packages\urllib3\connectionpool.py", line 843, in urlopen
    retries = retries.increment(
              ^^^^^^^^^^^^^^^^^^
  File "C:\Users\nifei\Downloads\DeepSort_Tutorial\.venv\Lib\site-packages\urllib3\util\retry.py", line 519, in increment
    raise MaxRetryError(_pool, url, reason) from reason  # type: ignore[arg-type]
    ^^^^^^^^^^^^^^^^^^^^^^^^^^^^^^^^^^^^^^^^^^^^^^^^^^^
urllib3.exceptions.MaxRetryError: HTTPSConnectionPool(host='oauth2.googleapis.com', port=443): Max retries exceeded with url: /token (Caused by NameResolutionError("<urllib3.connection.HTTPSConnection object at 0x0000029BDCBA8770>: Failed to resolve 'oauth2.googleapis.com' ([Errno 11001] getaddrinfo failed)"))

During handling of the above exception, another exception occurred:

Traceback (most recent call last):
  File "C:\Users\nifei\Downloads\DeepSort_Tutorial\.venv\Lib\site-packages\google\auth\transport\requests.py", line 187, in __call__
    response = self.session.request(
               ^^^^^^^^^^^^^^^^^^^^^
  File "C:\Users\nifei\Downloads\DeepSort_Tutorial\.venv\Lib\site-packages\requests\sessions.py", line 589, in request
    resp = self.send(prep, **send_kwargs)
           ^^^^^^^^^^^^^^^^^^^^^^^^^^^^^^
  File "C:\Users\nifei\Downloads\DeepSort_Tutorial\.venv\Lib\site-packages\requests\sessions.py", line 703, in send
    r = adapter.send(request, **kwargs)
        ^^^^^^^^^^^^^^^^^^^^^^^^^^^^^^^
  File "C:\Users\nifei\Downloads\DeepSort_Tutorial\.venv\Lib\site-packages\requests\adapters.py", line 700, in send
    raise ConnectionError(e, request=request)
requests.exceptions.ConnectionError: HTTPSConnectionPool(host='oauth2.googleapis.com', port=443): Max retries exceeded with url: /token (Caused by NameResolutionError("<urllib3.connection.HTTPSConnection object at 0x0000029BDCBA8770>: Failed to resolve 'oauth2.googleapis.com' ([Errno 11001] getaddrinfo failed)"))

The above exception was the direct cause of the following exception:

Traceback (most recent call last):
  File "C:\Users\nifei\Downloads\DeepSort_Tutorial\.venv\Lib\site-packages\grpc\_plugin_wrapping.py", line 105, in __call__
    self._metadata_plugin(
  File "C:\Users\nifei\Downloads\DeepSort_Tutorial\.venv\Lib\site-packages\google\auth\transport\grpc.py", line 95, in __call__
    callback(self._get_authorization_headers(context), None)
             ^^^^^^^^^^^^^^^^^^^^^^^^^^^^^^^^^^^^^^^^
  File "C:\Users\nifei\Downloads\DeepSort_Tutorial\.venv\Lib\site-packages\google\auth\transport\grpc.py", line 81, in _get_authorization_headers
    self._credentials.before_request(
  File "C:\Users\nifei\Downloads\DeepSort_Tutorial\.venv\Lib\site-packages\google\auth\credentials.py", line 239, in before_request
    self._blocking_refresh(request)
  File "C:\Users\nifei\Downloads\DeepSort_Tutorial\.venv\Lib\site-packages\google\auth\credentials.py", line 202, in _blocking_refresh
    self.refresh(request)
  File "C:\Users\nifei\Downloads\DeepSort_Tutorial\.venv\Lib\site-packages\google\oauth2\service_account.py", line 448, in refresh
    access_token, expiry, _ = _client.jwt_grant(
                              ^^^^^^^^^^^^^^^^^^
  File "C:\Users\nifei\Downloads\DeepSort_Tutorial\.venv\Lib\site-packages\google\oauth2\_client.py", line 298, in jwt_grant
    response_data = _token_endpoint_request(
                    ^^^^^^^^^^^^^^^^^^^^^^^^
  File "C:\Users\nifei\Downloads\DeepSort_Tutorial\.venv\Lib\site-packages\google\oauth2\_client.py", line 258, in _token_endpoint_request
    response_status_ok, response_data, retryable_error = _token_endpoint_request_no_throw(
                                                         ^^^^^^^^^^^^^^^^^^^^^^^^^^^^^^^^^
  File "C:\Users\nifei\Downloads\DeepSort_Tutorial\.venv\Lib\site-packages\google\oauth2\_client.py", line 191, in _token_endpoint_request_no_throw
    response = request(
               ^^^^^^^^
  File "C:\Users\nifei\Downloads\DeepSort_Tutorial\.venv\Lib\site-packages\google\auth\transport\requests.py", line 193, in __call__
    raise new_exc from caught_exc
google.auth.exceptions.TransportError: HTTPSConnectionPool(host='oauth2.googleapis.com', port=443): Max retries exceeded with url: /token (Caused by NameResolutionError("<urllib3.connection.HTTPSConnection object at 0x0000029BDCBA8770>: Failed to resolve 'oauth2.googleapis.com' ([Errno 11001] getaddrinfo failed)"))
[2024-11-07 14:12:28,406][grpc._plugin_wrapping][ERROR] - AuthMetadataPluginCallback "<google.auth.transport.grpc.AuthMetadataPlugin object at 0x0000029BDCBA9A60>" raised exception!
Traceback (most recent call last):
  File "C:\Users\nifei\Downloads\DeepSort_Tutorial\.venv\Lib\site-packages\urllib3\connection.py", line 196, in _new_conn
    sock = connection.create_connection(
           ^^^^^^^^^^^^^^^^^^^^^^^^^^^^^
  File "C:\Users\nifei\Downloads\DeepSort_Tutorial\.venv\Lib\site-packages\urllib3\util\connection.py", line 60, in create_connection
    for res in socket.getaddrinfo(host, port, family, socket.SOCK_STREAM):
               ^^^^^^^^^^^^^^^^^^^^^^^^^^^^^^^^^^^^^^^^^^^^^^^^^^^^^^^^^^
  File "C:\Users\nifei\AppData\Local\Programs\Python\Python312\Lib\socket.py", line 963, in getaddrinfo
    for res in _socket.getaddrinfo(host, port, family, type, proto, flags):
               ^^^^^^^^^^^^^^^^^^^^^^^^^^^^^^^^^^^^^^^^^^^^^^^^^^^^^^^^^^^
socket.gaierror: [Errno 11001] getaddrinfo failed

The above exception was the direct cause of the following exception:

Traceback (most recent call last):
  File "C:\Users\nifei\Downloads\DeepSort_Tutorial\.venv\Lib\site-packages\urllib3\connectionpool.py", line 789, in urlopen
    response = self._make_request(
               ^^^^^^^^^^^^^^^^^^^
  File "C:\Users\nifei\Downloads\DeepSort_Tutorial\.venv\Lib\site-packages\urllib3\connectionpool.py", line 490, in _make_request
    raise new_e
  File "C:\Users\nifei\Downloads\DeepSort_Tutorial\.venv\Lib\site-packages\urllib3\connectionpool.py", line 466, in _make_request
    self._validate_conn(conn)
  File "C:\Users\nifei\Downloads\DeepSort_Tutorial\.venv\Lib\site-packages\urllib3\connectionpool.py", line 1095, in _validate_conn
    conn.connect()
  File "C:\Users\nifei\Downloads\DeepSort_Tutorial\.venv\Lib\site-packages\urllib3\connection.py", line 615, in connect
    self.sock = sock = self._new_conn()
                       ^^^^^^^^^^^^^^^^
  File "C:\Users\nifei\Downloads\DeepSort_Tutorial\.venv\Lib\site-packages\urllib3\connection.py", line 203, in _new_conn
    raise NameResolutionError(self.host, self, e) from e
urllib3.exceptions.NameResolutionError: <urllib3.connection.HTTPSConnection object at 0x0000029BDC6EB560>: Failed to resolve 'oauth2.googleapis.com' ([Errno 11001] getaddrinfo failed)

The above exception was the direct cause of the following exception:

Traceback (most recent call last):
  File "C:\Users\nifei\Downloads\DeepSort_Tutorial\.venv\Lib\site-packages\requests\adapters.py", line 667, in send
    resp = conn.urlopen(
           ^^^^^^^^^^^^^
  File "C:\Users\nifei\Downloads\DeepSort_Tutorial\.venv\Lib\site-packages\urllib3\connectionpool.py", line 843, in urlopen
    retries = retries.increment(
              ^^^^^^^^^^^^^^^^^^
  File "C:\Users\nifei\Downloads\DeepSort_Tutorial\.venv\Lib\site-packages\urllib3\util\retry.py", line 519, in increment
    raise MaxRetryError(_pool, url, reason) from reason  # type: ignore[arg-type]
    ^^^^^^^^^^^^^^^^^^^^^^^^^^^^^^^^^^^^^^^^^^^^^^^^^^^
urllib3.exceptions.MaxRetryError: HTTPSConnectionPool(host='oauth2.googleapis.com', port=443): Max retries exceeded with url: /token (Caused by NameResolutionError("<urllib3.connection.HTTPSConnection object at 0x0000029BDC6EB560>: Failed to resolve 'oauth2.googleapis.com' ([Errno 11001] getaddrinfo failed)"))

During handling of the above exception, another exception occurred:

Traceback (most recent call last):
  File "C:\Users\nifei\Downloads\DeepSort_Tutorial\.venv\Lib\site-packages\google\auth\transport\requests.py", line 187, in __call__
    response = self.session.request(
               ^^^^^^^^^^^^^^^^^^^^^
  File "C:\Users\nifei\Downloads\DeepSort_Tutorial\.venv\Lib\site-packages\requests\sessions.py", line 589, in request
    resp = self.send(prep, **send_kwargs)
           ^^^^^^^^^^^^^^^^^^^^^^^^^^^^^^
  File "C:\Users\nifei\Downloads\DeepSort_Tutorial\.venv\Lib\site-packages\requests\sessions.py", line 703, in send
    r = adapter.send(request, **kwargs)
        ^^^^^^^^^^^^^^^^^^^^^^^^^^^^^^^
  File "C:\Users\nifei\Downloads\DeepSort_Tutorial\.venv\Lib\site-packages\requests\adapters.py", line 700, in send
    raise ConnectionError(e, request=request)
requests.exceptions.ConnectionError: HTTPSConnectionPool(host='oauth2.googleapis.com', port=443): Max retries exceeded with url: /token (Caused by NameResolutionError("<urllib3.connection.HTTPSConnection object at 0x0000029BDC6EB560>: Failed to resolve 'oauth2.googleapis.com' ([Errno 11001] getaddrinfo failed)"))

The above exception was the direct cause of the following exception:

Traceback (most recent call last):
  File "C:\Users\nifei\Downloads\DeepSort_Tutorial\.venv\Lib\site-packages\grpc\_plugin_wrapping.py", line 105, in __call__
    self._metadata_plugin(
  File "C:\Users\nifei\Downloads\DeepSort_Tutorial\.venv\Lib\site-packages\google\auth\transport\grpc.py", line 95, in __call__
    callback(self._get_authorization_headers(context), None)
             ^^^^^^^^^^^^^^^^^^^^^^^^^^^^^^^^^^^^^^^^
  File "C:\Users\nifei\Downloads\DeepSort_Tutorial\.venv\Lib\site-packages\google\auth\transport\grpc.py", line 81, in _get_authorization_headers
    self._credentials.before_request(
  File "C:\Users\nifei\Downloads\DeepSort_Tutorial\.venv\Lib\site-packages\google\auth\credentials.py", line 239, in before_request
    self._blocking_refresh(request)
  File "C:\Users\nifei\Downloads\DeepSort_Tutorial\.venv\Lib\site-packages\google\auth\credentials.py", line 202, in _blocking_refresh
    self.refresh(request)
  File "C:\Users\nifei\Downloads\DeepSort_Tutorial\.venv\Lib\site-packages\google\oauth2\service_account.py", line 448, in refresh
    access_token, expiry, _ = _client.jwt_grant(
                              ^^^^^^^^^^^^^^^^^^
  File "C:\Users\nifei\Downloads\DeepSort_Tutorial\.venv\Lib\site-packages\google\oauth2\_client.py", line 298, in jwt_grant
    response_data = _token_endpoint_request(
                    ^^^^^^^^^^^^^^^^^^^^^^^^
  File "C:\Users\nifei\Downloads\DeepSort_Tutorial\.venv\Lib\site-packages\google\oauth2\_client.py", line 258, in _token_endpoint_request
    response_status_ok, response_data, retryable_error = _token_endpoint_request_no_throw(
                                                         ^^^^^^^^^^^^^^^^^^^^^^^^^^^^^^^^^
  File "C:\Users\nifei\Downloads\DeepSort_Tutorial\.venv\Lib\site-packages\google\oauth2\_client.py", line 191, in _token_endpoint_request_no_throw
    response = request(
               ^^^^^^^^
  File "C:\Users\nifei\Downloads\DeepSort_Tutorial\.venv\Lib\site-packages\google\auth\transport\requests.py", line 193, in __call__
    raise new_exc from caught_exc
google.auth.exceptions.TransportError: HTTPSConnectionPool(host='oauth2.googleapis.com', port=443): Max retries exceeded with url: /token (Caused by NameResolutionError("<urllib3.connection.HTTPSConnection object at 0x0000029BDC6EB560>: Failed to resolve 'oauth2.googleapis.com' ([Errno 11001] getaddrinfo failed)"))
[2024-11-07 14:12:28,610][grpc._plugin_wrapping][ERROR] - AuthMetadataPluginCallback "<google.auth.transport.grpc.AuthMetadataPlugin object at 0x0000029BDCBA9A60>" raised exception!
Traceback (most recent call last):
  File "C:\Users\nifei\Downloads\DeepSort_Tutorial\.venv\Lib\site-packages\urllib3\connection.py", line 196, in _new_conn
    sock = connection.create_connection(
           ^^^^^^^^^^^^^^^^^^^^^^^^^^^^^
  File "C:\Users\nifei\Downloads\DeepSort_Tutorial\.venv\Lib\site-packages\urllib3\util\connection.py", line 60, in create_connection
    for res in socket.getaddrinfo(host, port, family, socket.SOCK_STREAM):
               ^^^^^^^^^^^^^^^^^^^^^^^^^^^^^^^^^^^^^^^^^^^^^^^^^^^^^^^^^^
  File "C:\Users\nifei\AppData\Local\Programs\Python\Python312\Lib\socket.py", line 963, in getaddrinfo
    for res in _socket.getaddrinfo(host, port, family, type, proto, flags):
               ^^^^^^^^^^^^^^^^^^^^^^^^^^^^^^^^^^^^^^^^^^^^^^^^^^^^^^^^^^^
socket.gaierror: [Errno 11001] getaddrinfo failed

The above exception was the direct cause of the following exception:

Traceback (most recent call last):
  File "C:\Users\nifei\Downloads\DeepSort_Tutorial\.venv\Lib\site-packages\urllib3\connectionpool.py", line 789, in urlopen
    response = self._make_request(
               ^^^^^^^^^^^^^^^^^^^
  File "C:\Users\nifei\Downloads\DeepSort_Tutorial\.venv\Lib\site-packages\urllib3\connectionpool.py", line 490, in _make_request
    raise new_e
  File "C:\Users\nifei\Downloads\DeepSort_Tutorial\.venv\Lib\site-packages\urllib3\connectionpool.py", line 466, in _make_request
    self._validate_conn(conn)
  File "C:\Users\nifei\Downloads\DeepSort_Tutorial\.venv\Lib\site-packages\urllib3\connectionpool.py", line 1095, in _validate_conn
    conn.connect()
  File "C:\Users\nifei\Downloads\DeepSort_Tutorial\.venv\Lib\site-packages\urllib3\connection.py", line 615, in connect
    self.sock = sock = self._new_conn()
                       ^^^^^^^^^^^^^^^^
  File "C:\Users\nifei\Downloads\DeepSort_Tutorial\.venv\Lib\site-packages\urllib3\connection.py", line 203, in _new_conn
    raise NameResolutionError(self.host, self, e) from e
urllib3.exceptions.NameResolutionError: <urllib3.connection.HTTPSConnection object at 0x0000029BDC6AF050>: Failed to resolve 'oauth2.googleapis.com' ([Errno 11001] getaddrinfo failed)

The above exception was the direct cause of the following exception:

Traceback (most recent call last):
  File "C:\Users\nifei\Downloads\DeepSort_Tutorial\.venv\Lib\site-packages\requests\adapters.py", line 667, in send
    resp = conn.urlopen(
           ^^^^^^^^^^^^^
  File "C:\Users\nifei\Downloads\DeepSort_Tutorial\.venv\Lib\site-packages\urllib3\connectionpool.py", line 843, in urlopen
    retries = retries.increment(
              ^^^^^^^^^^^^^^^^^^
  File "C:\Users\nifei\Downloads\DeepSort_Tutorial\.venv\Lib\site-packages\urllib3\util\retry.py", line 519, in increment
    raise MaxRetryError(_pool, url, reason) from reason  # type: ignore[arg-type]
    ^^^^^^^^^^^^^^^^^^^^^^^^^^^^^^^^^^^^^^^^^^^^^^^^^^^
urllib3.exceptions.MaxRetryError: HTTPSConnectionPool(host='oauth2.googleapis.com', port=443): Max retries exceeded with url: /token (Caused by NameResolutionError("<urllib3.connection.HTTPSConnection object at 0x0000029BDC6AF050>: Failed to resolve 'oauth2.googleapis.com' ([Errno 11001] getaddrinfo failed)"))

During handling of the above exception, another exception occurred:

Traceback (most recent call last):
  File "C:\Users\nifei\Downloads\DeepSort_Tutorial\.venv\Lib\site-packages\google\auth\transport\requests.py", line 187, in __call__
    response = self.session.request(
               ^^^^^^^^^^^^^^^^^^^^^
  File "C:\Users\nifei\Downloads\DeepSort_Tutorial\.venv\Lib\site-packages\requests\sessions.py", line 589, in request
    resp = self.send(prep, **send_kwargs)
           ^^^^^^^^^^^^^^^^^^^^^^^^^^^^^^
  File "C:\Users\nifei\Downloads\DeepSort_Tutorial\.venv\Lib\site-packages\requests\sessions.py", line 703, in send
    r = adapter.send(request, **kwargs)
        ^^^^^^^^^^^^^^^^^^^^^^^^^^^^^^^
  File "C:\Users\nifei\Downloads\DeepSort_Tutorial\.venv\Lib\site-packages\requests\adapters.py", line 700, in send
    raise ConnectionError(e, request=request)
requests.exceptions.ConnectionError: HTTPSConnectionPool(host='oauth2.googleapis.com', port=443): Max retries exceeded with url: /token (Caused by NameResolutionError("<urllib3.connection.HTTPSConnection object at 0x0000029BDC6AF050>: Failed to resolve 'oauth2.googleapis.com' ([Errno 11001] getaddrinfo failed)"))

The above exception was the direct cause of the following exception:

Traceback (most recent call last):
  File "C:\Users\nifei\Downloads\DeepSort_Tutorial\.venv\Lib\site-packages\grpc\_plugin_wrapping.py", line 105, in __call__
    self._metadata_plugin(
  File "C:\Users\nifei\Downloads\DeepSort_Tutorial\.venv\Lib\site-packages\google\auth\transport\grpc.py", line 95, in __call__
    callback(self._get_authorization_headers(context), None)
             ^^^^^^^^^^^^^^^^^^^^^^^^^^^^^^^^^^^^^^^^
  File "C:\Users\nifei\Downloads\DeepSort_Tutorial\.venv\Lib\site-packages\google\auth\transport\grpc.py", line 81, in _get_authorization_headers
    self._credentials.before_request(
  File "C:\Users\nifei\Downloads\DeepSort_Tutorial\.venv\Lib\site-packages\google\auth\credentials.py", line 239, in before_request
    self._blocking_refresh(request)
  File "C:\Users\nifei\Downloads\DeepSort_Tutorial\.venv\Lib\site-packages\google\auth\credentials.py", line 202, in _blocking_refresh
    self.refresh(request)
  File "C:\Users\nifei\Downloads\DeepSort_Tutorial\.venv\Lib\site-packages\google\oauth2\service_account.py", line 448, in refresh
    access_token, expiry, _ = _client.jwt_grant(
                              ^^^^^^^^^^^^^^^^^^
  File "C:\Users\nifei\Downloads\DeepSort_Tutorial\.venv\Lib\site-packages\google\oauth2\_client.py", line 298, in jwt_grant
    response_data = _token_endpoint_request(
                    ^^^^^^^^^^^^^^^^^^^^^^^^
  File "C:\Users\nifei\Downloads\DeepSort_Tutorial\.venv\Lib\site-packages\google\oauth2\_client.py", line 258, in _token_endpoint_request
    response_status_ok, response_data, retryable_error = _token_endpoint_request_no_throw(
                                                         ^^^^^^^^^^^^^^^^^^^^^^^^^^^^^^^^^
  File "C:\Users\nifei\Downloads\DeepSort_Tutorial\.venv\Lib\site-packages\google\oauth2\_client.py", line 191, in _token_endpoint_request_no_throw
    response = request(
               ^^^^^^^^
  File "C:\Users\nifei\Downloads\DeepSort_Tutorial\.venv\Lib\site-packages\google\auth\transport\requests.py", line 193, in __call__
    raise new_exc from caught_exc
google.auth.exceptions.TransportError: HTTPSConnectionPool(host='oauth2.googleapis.com', port=443): Max retries exceeded with url: /token (Caused by NameResolutionError("<urllib3.connection.HTTPSConnection object at 0x0000029BDC6AF050>: Failed to resolve 'oauth2.googleapis.com' ([Errno 11001] getaddrinfo failed)"))
[2024-11-07 14:12:29,684][grpc._plugin_wrapping][ERROR] - AuthMetadataPluginCallback "<google.auth.transport.grpc.AuthMetadataPlugin object at 0x0000029BDCBA9A60>" raised exception!
Traceback (most recent call last):
  File "C:\Users\nifei\Downloads\DeepSort_Tutorial\.venv\Lib\site-packages\urllib3\connection.py", line 196, in _new_conn
    sock = connection.create_connection(
           ^^^^^^^^^^^^^^^^^^^^^^^^^^^^^
  File "C:\Users\nifei\Downloads\DeepSort_Tutorial\.venv\Lib\site-packages\urllib3\util\connection.py", line 60, in create_connection
    for res in socket.getaddrinfo(host, port, family, socket.SOCK_STREAM):
               ^^^^^^^^^^^^^^^^^^^^^^^^^^^^^^^^^^^^^^^^^^^^^^^^^^^^^^^^^^
  File "C:\Users\nifei\AppData\Local\Programs\Python\Python312\Lib\socket.py", line 963, in getaddrinfo
    for res in _socket.getaddrinfo(host, port, family, type, proto, flags):
               ^^^^^^^^^^^^^^^^^^^^^^^^^^^^^^^^^^^^^^^^^^^^^^^^^^^^^^^^^^^
socket.gaierror: [Errno 11001] getaddrinfo failed

The above exception was the direct cause of the following exception:

Traceback (most recent call last):
  File "C:\Users\nifei\Downloads\DeepSort_Tutorial\.venv\Lib\site-packages\urllib3\connectionpool.py", line 789, in urlopen
    response = self._make_request(
               ^^^^^^^^^^^^^^^^^^^
  File "C:\Users\nifei\Downloads\DeepSort_Tutorial\.venv\Lib\site-packages\urllib3\connectionpool.py", line 490, in _make_request
    raise new_e
  File "C:\Users\nifei\Downloads\DeepSort_Tutorial\.venv\Lib\site-packages\urllib3\connectionpool.py", line 466, in _make_request
    self._validate_conn(conn)
  File "C:\Users\nifei\Downloads\DeepSort_Tutorial\.venv\Lib\site-packages\urllib3\connectionpool.py", line 1095, in _validate_conn
    conn.connect()
  File "C:\Users\nifei\Downloads\DeepSort_Tutorial\.venv\Lib\site-packages\urllib3\connection.py", line 615, in connect
    self.sock = sock = self._new_conn()
                       ^^^^^^^^^^^^^^^^
  File "C:\Users\nifei\Downloads\DeepSort_Tutorial\.venv\Lib\site-packages\urllib3\connection.py", line 203, in _new_conn
    raise NameResolutionError(self.host, self, e) from e
urllib3.exceptions.NameResolutionError: <urllib3.connection.HTTPSConnection object at 0x0000029BDC6AFBC0>: Failed to resolve 'oauth2.googleapis.com' ([Errno 11001] getaddrinfo failed)

The above exception was the direct cause of the following exception:

Traceback (most recent call last):
  File "C:\Users\nifei\Downloads\DeepSort_Tutorial\.venv\Lib\site-packages\requests\adapters.py", line 667, in send
    resp = conn.urlopen(
           ^^^^^^^^^^^^^
  File "C:\Users\nifei\Downloads\DeepSort_Tutorial\.venv\Lib\site-packages\urllib3\connectionpool.py", line 843, in urlopen
    retries = retries.increment(
              ^^^^^^^^^^^^^^^^^^
  File "C:\Users\nifei\Downloads\DeepSort_Tutorial\.venv\Lib\site-packages\urllib3\util\retry.py", line 519, in increment
    raise MaxRetryError(_pool, url, reason) from reason  # type: ignore[arg-type]
    ^^^^^^^^^^^^^^^^^^^^^^^^^^^^^^^^^^^^^^^^^^^^^^^^^^^
urllib3.exceptions.MaxRetryError: HTTPSConnectionPool(host='oauth2.googleapis.com', port=443): Max retries exceeded with url: /token (Caused by NameResolutionError("<urllib3.connection.HTTPSConnection object at 0x0000029BDC6AFBC0>: Failed to resolve 'oauth2.googleapis.com' ([Errno 11001] getaddrinfo failed)"))

During handling of the above exception, another exception occurred:

Traceback (most recent call last):
  File "C:\Users\nifei\Downloads\DeepSort_Tutorial\.venv\Lib\site-packages\google\auth\transport\requests.py", line 187, in __call__
    response = self.session.request(
               ^^^^^^^^^^^^^^^^^^^^^
  File "C:\Users\nifei\Downloads\DeepSort_Tutorial\.venv\Lib\site-packages\requests\sessions.py", line 589, in request
    resp = self.send(prep, **send_kwargs)
           ^^^^^^^^^^^^^^^^^^^^^^^^^^^^^^
  File "C:\Users\nifei\Downloads\DeepSort_Tutorial\.venv\Lib\site-packages\requests\sessions.py", line 703, in send
    r = adapter.send(request, **kwargs)
        ^^^^^^^^^^^^^^^^^^^^^^^^^^^^^^^
  File "C:\Users\nifei\Downloads\DeepSort_Tutorial\.venv\Lib\site-packages\requests\adapters.py", line 700, in send
    raise ConnectionError(e, request=request)
requests.exceptions.ConnectionError: HTTPSConnectionPool(host='oauth2.googleapis.com', port=443): Max retries exceeded with url: /token (Caused by NameResolutionError("<urllib3.connection.HTTPSConnection object at 0x0000029BDC6AFBC0>: Failed to resolve 'oauth2.googleapis.com' ([Errno 11001] getaddrinfo failed)"))

The above exception was the direct cause of the following exception:

Traceback (most recent call last):
  File "C:\Users\nifei\Downloads\DeepSort_Tutorial\.venv\Lib\site-packages\grpc\_plugin_wrapping.py", line 105, in __call__
    self._metadata_plugin(
  File "C:\Users\nifei\Downloads\DeepSort_Tutorial\.venv\Lib\site-packages\google\auth\transport\grpc.py", line 95, in __call__
    callback(self._get_authorization_headers(context), None)
             ^^^^^^^^^^^^^^^^^^^^^^^^^^^^^^^^^^^^^^^^
  File "C:\Users\nifei\Downloads\DeepSort_Tutorial\.venv\Lib\site-packages\google\auth\transport\grpc.py", line 81, in _get_authorization_headers
    self._credentials.before_request(
  File "C:\Users\nifei\Downloads\DeepSort_Tutorial\.venv\Lib\site-packages\google\auth\credentials.py", line 239, in before_request
    self._blocking_refresh(request)
  File "C:\Users\nifei\Downloads\DeepSort_Tutorial\.venv\Lib\site-packages\google\auth\credentials.py", line 202, in _blocking_refresh
    self.refresh(request)
  File "C:\Users\nifei\Downloads\DeepSort_Tutorial\.venv\Lib\site-packages\google\oauth2\service_account.py", line 448, in refresh
    access_token, expiry, _ = _client.jwt_grant(
                              ^^^^^^^^^^^^^^^^^^
  File "C:\Users\nifei\Downloads\DeepSort_Tutorial\.venv\Lib\site-packages\google\oauth2\_client.py", line 298, in jwt_grant
    response_data = _token_endpoint_request(
                    ^^^^^^^^^^^^^^^^^^^^^^^^
  File "C:\Users\nifei\Downloads\DeepSort_Tutorial\.venv\Lib\site-packages\google\oauth2\_client.py", line 258, in _token_endpoint_request
    response_status_ok, response_data, retryable_error = _token_endpoint_request_no_throw(
                                                         ^^^^^^^^^^^^^^^^^^^^^^^^^^^^^^^^^
  File "C:\Users\nifei\Downloads\DeepSort_Tutorial\.venv\Lib\site-packages\google\oauth2\_client.py", line 191, in _token_endpoint_request_no_throw
    response = request(
               ^^^^^^^^
  File "C:\Users\nifei\Downloads\DeepSort_Tutorial\.venv\Lib\site-packages\google\auth\transport\requests.py", line 193, in __call__
    raise new_exc from caught_exc
google.auth.exceptions.TransportError: HTTPSConnectionPool(host='oauth2.googleapis.com', port=443): Max retries exceeded with url: /token (Caused by NameResolutionError("<urllib3.connection.HTTPSConnection object at 0x0000029BDC6AFBC0>: Failed to resolve 'oauth2.googleapis.com' ([Errno 11001] getaddrinfo failed)"))
[2024-11-07 22:41:05,225][root.tracker][INFO] - Loading weights from deep_sort_pytorch/deep_sort/deep/checkpoint/ckpt.t7... Done!
[2024-11-07 23:12:24,827][root.tracker][INFO] - Loading weights from deep_sort_pytorch/deep_sort/deep/checkpoint/ckpt.t7... Done!
